Workbook
Name _3_col: '3-col'!$A$1:$M$47
Name ancestor: ancestor!$A$1:$M$5
Name graph_colouring: graph_colouring!$A$1:$M$201
Name hanoi_tower: hanoi_tower!$A$1:$M$133
Name keys: keys!$A$1:$M$3
Name labyrinth: labyrinth!$A$1:$M$647
Name ladder: ladder!$A$1:$M$41
Name network: network!$A$1:$M$3
Name stable_marriage: stable_marriage!$A$1:$M$341

Sheet refined_data
C1: ASP Mapper | E1: ASP Mapper %- | F1: ASP Mapper %- 2 | H1: Sorted values %- 2 | L1: Sorted values %-
A2: Problem | B2: AS | C2: NEW | D2: OLD
A3: 3-col 0001.out | B3: 0 | C3: =AVERAGE('3-col'!C1:L1) -> 0.0020055862 | D3: =AVERAGE('3-col'!C25:L25) -> 0.0004720068 | E3: =(C3 - D3)/D3 -> 3.2490621 | F3: =ABS(C3 - D3) / (ABS(C3 + D3) / 2) -> 1.2379591 | H3: keys 0001.out | I3: 0 | J3: 0.83811134 | L3: keys 0001.out | M3: 0 | N3: 1.4426707
B4: 1 | C4: =AVERAGE('3-col'!C2:L2) -> 0.0009324911 | D4: =AVERAGE('3-col'!C26:L26) -> 3.72734e-05 | E4: =(C4 - D4)/D4 -> 24.017602 | F4: =ABS(C4 - D4) / (ABS(C4 + D4) / 2) -> 1.8462579 | H4: 3-col 0001.out | I4: 0 | J4: 1.2379591 | L4: 3-col 0001.out | M4: 0 | N4: 3.2490621
B5: 2 | C5: =AVERAGE('3-col'!C3:L3) -> 0.0010277512 | D5: =AVERAGE('3-col'!C27:L27) -> 1.98264e-05 | E5: =(C5 - D5)/D5 -> 50.83751 | F5: =ABS(C5 - D5) / (ABS(C5 + D5) / 2) -> 1.9242962 | H5: graph_colouring 0001.out | I5: 18 | J5: 1.6563751 | L5: graph_colouring 0001.out | M5: 18 | N5: 9.6406011
B6: 3 | C6: =AVERAGE('3-col'!C4:L4) -> 0.0008775839 | D6: =AVERAGE('3-col'!C28:L28) -> 2.45847e-05 | E6: =(C6 - D6)/D6 -> 34.696344 | F6: =ABS(C6 - D6) / (ABS(C6 + D6) / 2) -> 1.8909973 | H6: graph_colouring 0001.out | I6: 2 | J6: 1.6950624 | L6: graph_colouring 0001.out | M6: 2 | N6: 11.117438
B7: 4 | C7: =AVERAGE('3-col'!C5:L5) -> 0.0006109778 | D7: =AVERAGE('3-col'!C29:L29) -> 1.894e-05 | E7: =(C7 - D7)/D7 -> 31.258596 | F7: =ABS(C7 - D7) / (ABS(C7 + D7) / 2) -> 1.8797303 | H7: 3-col 0002.out | I7: 2 | J7: 1.7513245 | L7: 3-col 0002.out | M7: 2 | N7: 14.085219
B8: 5 | C8: =AVERAGE('3-col'!C6:L6) -> 0.0005308327 | D8: =AVERAGE('3-col'!C30:L30) -> 2.0946e-05 | E8: =(C8 - D8)/D8 -> 24.342915 | F8: =ABS(C8 - D8) / (ABS(C8 + D8) / 2) -> 1.8481565 | H8: 3-col 0002.out | I8: 4 | J8: 1.7549444 | L8: 3-col 0002.out | M8: 4 | N8: 14.322825
B9: 6 | C9: =AVERAGE('3-col'!C7:L7) -> 0.0006301979 | D9: =AVERAGE('3-col'!C31:L31) -> 2.01996e-05 | E9: =(C9 - D9)/D9 -> 30.198534 | F9: =ABS(C9 - D9) / (ABS(C9 + D9) / 2) -> 1.8757707 | H9: 3-col 0002.out | I9: 10 | J9: 1.7648299 | L9: 3-col 0002.out | M9: 10 | N9: 15.008964
B10: 7 | C10: =AVERAGE('3-col'!C8:L8) -> 0.000487448 | D10: =AVERAGE('3-col'!C32:L32) -> 2.06193e-05 | E10: =(C10 - D10)/D10 -> 22.640376 | F10: =ABS(C10 - D10) / (ABS(C10 + D10) / 2) -> 1.8376648 | H10: graph_colouring 0001.out | I10: 1 | J10: 1.7728273 | L10: graph_colouring 0001.out | M10: 1 | N10: 15.607746
B11: 8 | C11: =AVERAGE('3-col'!C9:L9) -> 0.0005617151 | D11: =AVERAGE('3-col'!C33:L33) -> 1.76805e-05 | E11: =(C11 - D11)/D11 -> 30.770318 | F11: =ABS(C11 - D11) / (ABS(C11 + D11) / 2) -> 1.8779383 | H11: 3-col 0002.out | I11: 3 | J11: 1.7890443 | L11: 3-col 0002.out | M11: 3 | N11: 16.961325
B12: 9 | C12: =AVERAGE('3-col'!C10:L10) -> 0.0004598776 | D12: =AVERAGE('3-col'!C34:L34) -> 1.44615e-05 | E12: =(C12 - D12)/D12 -> 30.800131 | F12: =ABS(C12 - D12) / (ABS(C12 + D12) / 2) -> 1.8780493 | H12: 3-col 0002.out | I12: 7 | J12: 1.8059827 | L12: 3-col 0002.out | M12: 7 | N12: 18.616713
A13: 3-col 0002.out | B13: 0 | C13: =AVERAGE('3-col'!C11:L11) -> 0.0008086349 | D13: =AVERAGE('3-col'!C35:L35) -> 3.6947e-05 | E13: =(C13 - D13)/D13 -> 20.886348 | F13: =ABS(C13 - D13) / (ABS(C13 + D13) / 2) -> 1.8252233 | H13: graph_colouring 0001.out | I13: 0 | J13: 1.8122383 | L13: graph_colouring 0001.out | M13: 0 | N13: 19.303601
B14: 1 | C14: =AVERAGE('3-col'!C12:L12) -> 0.0006923359 | D14: =AVERAGE('3-col'!C36:L36) -> 3.15355e-05 | E14: =(C14 - D14)/D14 -> 20.954175 | F14: =ABS(C14 - D14) / (ABS(C14 + D14) / 2) -> 1.8257398 | H14: 3-col 0002.out | I14: 12 | J14: 1.8127232 | L14: 3-col 0002.out | M14: 12 | N14: 19.35876
B15: 2 | C15: =AVERAGE('3-col'!C13:L13) -> 0.0004792378 | D15: =AVERAGE('3-col'!C37:L37) -> 3.17687e-05 | E15: =(C15 - D15)/D15 -> 14.085219 | F15: =ABS(C15 - D15) / (ABS(C15 + D15) / 2) -> 1.7513245 | H15: 3-col 0002.out | I15: 8 | J15: 1.8218607 | L15: 3-col 0002.out | M15: 8 | N15: 20.454342
B16: 3 | C16: =AVERAGE('3-col'!C14:L14) -> 0.0005412825 | D16: =AVERAGE('3-col'!C38:L38) -> 3.0136e-05 | E16: =(C16 - D16)/D16 -> 16.961325 | F16: =ABS(C16 - D16) / (ABS(C16 + D16) / 2) -> 1.7890443 | H16: 3-col 0002.out | I16: 0 | J16: 1.8252233 | L16: 3-col 0002.out | M16: 0 | N16: 20.886348
B17: 4 | C17: =AVERAGE('3-col'!C15:L15) -> 0.0005711384 | D17: =AVERAGE('3-col'!C39:L39) -> 3.72737e-05 | E17: =(C17 - D17)/D17 -> 14.322825 | F17: =ABS(C17 - D17) / (ABS(C17 + D17) / 2) -> 1.7549444 | H17: 3-col 0002.out | I17: 1 | J17: 1.8257398 | L17: 3-col 0002.out | M17: 1 | N17: 20.954175
B18: 5 | C18: =AVERAGE('3-col'!C16:L16) -> 0.0008002376 | D18: =AVERAGE('3-col'!C40:L40) -> 2.35118e-05 | E18: =(C18 - D18)/D18 -> 33.035574 | F18: =ABS(C18 - D18) / (ABS(C18 + D18) / 2) -> 1.8858303 | H18: 3-col 0002.out | I18: 11 | J18: 1.8276938 | L18: 3-col 0002.out | M18: 11 | N18: 21.214487
B19: 6 | C19: =AVERAGE('3-col'!C17:L17) -> 0.0007639904 | D19: =AVERAGE('3-col'!C41:L41) -> 2.31384e-05 | E19: =(C19 - D19)/D19 -> 32.01829 | F19: =ABS(C19 - D19) / (ABS(C19 + D19) / 2) -> 1.8824162 | H19: 3-col 0001.out | I19: 7 | J19: 1.8376648 | L19: 3-col 0001.out | M19: 7 | N19: 22.640376
B20: 7 | C20: =AVERAGE('3-col'!C18:L18) -> 0.0004438301 | D20: =AVERAGE('3-col'!C42:L42) -> 2.26251e-05 | E20: =(C20 - D20)/D20 -> 18.616713 | F20: =ABS(C20 - D20) / (ABS(C20 + D20) / 2) -> 1.8059827 | H20: 3-col 0002.out | I20: 9 | J20: 1.8391372 | L20: 3-col 0002.out | M20: 9 | N20: 22.865913
B21: 8 | C21: =AVERAGE('3-col'!C19:L19) -> 0.000539463 | D21: =AVERAGE('3-col'!C43:L43) -> 2.51447e-05 | E21: =(C21 - D21)/D21 -> 20.454342 | F21: =ABS(C21 - D21) / (ABS(C21 + D21) / 2) -> 1.8218607 | H21: 3-col 0001.out | I21: 1 | J21: 1.8462579 | L21: 3-col 0001.out | M21: 1 | N21: 24.017602
B22: 9 | C22: =AVERAGE('3-col'!C20:L20) -> 0.0005566772 | D22: =AVERAGE('3-col'!C44:L44) -> 2.33252e-05 | E22: =(C22 - D22)/D22 -> 22.865913 | F22: =ABS(C22 - D22) / (ABS(C22 + D22) / 2) -> 1.8391372 | H22: 3-col 0001.out | I22: 5 | J22: 1.8481565 | L22: 3-col 0001.out | M22: 5 | N22: 24.342915
B23: 10 | C23: =AVERAGE('3-col'!C21:L21) -> 0.0004936524 | D23: =AVERAGE('3-col'!C45:L45) -> 3.0836e-05 | E23: =(C23 - D23)/D23 -> 15.008964 | F23: =ABS(C23 - D23) / (ABS(C23 + D23) / 2) -> 1.7648299 | H23: graph_colouring 0003.out | I23: 0 | J23: 1.8581752 | L23: graph_colouring 0003.out | M23: 0 | N23: 26.203805
B24: 11 | C24: =AVERAGE('3-col'!C22:L22) -> 0.0004539064 | D24: =AVERAGE('3-col'!C46:L46) -> 2.04329e-05 | E24: =(C24 - D24)/D24 -> 21.214487 | F24: =ABS(C24 - D24) / (ABS(C24 + D24) / 2) -> 1.8276938 | H24: ladder 0002.out | I24: 0 | J24: 1.8754788 | L24: ladder 0002.out | M24: 0 | N24: 30.123032
B25: 12 | C25: =AVERAGE('3-col'!C23:L23) -> 0.0002991679 | D25: =AVERAGE('3-col'!C47:L47) -> 1.46948e-05 | E25: =(C25 - D25)/D25 -> 19.35876 | F25: =ABS(C25 - D25) / (ABS(C25 + D25) / 2) -> 1.8127232 | H25: 3-col 0001.out | I25: 6 | J25: 1.8757707 | L25: 3-col 0001.out | M25: 6 | N25: 30.198534
A26: ancestor 0001.out | B26: 0 | C26: =AVERAGE(ancestor!C1:L1) -> 0.0086678426 | D26: =AVERAGE(ancestor!C4:L4) -> 0.0001146195 | E26: =(C26 - D26)/D26 -> 74.622757 | F26: =ABS(C26 - D26) / (ABS(C26 + D26) / 2) -> 1.9477962 | H26: 3-col 0001.out | I26: 8 | J26: 1.8779383 | L26: 3-col 0001.out | M26: 8 | N26: 30.770318
A27: ancestor 0002.out | B27: 0 | C27: =AVERAGE(ancestor!C2:L2) -> 0.022125402 | D27: =AVERAGE(ancestor!C5:L5) -> 0.0002376365 | E27: =(C27 - D27)/D27 -> 92.106077 | F27: =ABS(C27 - D27) / (ABS(C27 + D27) / 2) -> 1.9574948 | H27: 3-col 0001.out | I27: 9 | J27: 1.8780493 | L27: 3-col 0001.out | M27: 9 | N27: 30.800131
A28: graph_colouring 0001.out | B28: 0 | C28: =AVERAGE(graph_colouring!C1:L1) -> 0.0090814434 | D28: =AVERAGE(graph_colouring!C102:L102) -> 0.0004472824 | E28: =(C28 - D28)/D28 -> 19.303601 | F28: =ABS(C28 - D28) / (ABS(C28 + D28) / 2) -> 1.8122383 | H28: 3-col 0001.out | I28: 4 | J28: 1.8797303 | L28: 3-col 0001.out | M28: 4 | N28: 31.258596
B29: 1 | C29: =AVERAGE(graph_colouring!C2:L2) -> 0.0074740637 | D29: =AVERAGE(graph_colouring!C103:L103) -> 0.0004500348 | E29: =(C29 - D29)/D29 -> 15.607746 | F29: =ABS(C29 - D29) / (ABS(C29 + D29) / 2) -> 1.7728273 | H29: hanoi_tower 0040.out | I29: 0 | J29: 1.8797802 | L29: hanoi_tower 0040.out | M29: 0 | N29: 31.2724
B30: 2 | C30: =AVERAGE(graph_colouring!C3:L3) -> 0.0088229078 | D30: =AVERAGE(graph_colouring!C104:L104) -> 0.0007281166 | E30: =(C30 - D30)/D30 -> 11.117438 | F30: =ABS(C30 - D30) / (ABS(C30 + D30) / 2) -> 1.6950624 | H30: graph_colouring 0007.out | I30: 13 | J30: 1.8802772 | L30: graph_colouring 0007.out | M30: 13 | N30: 31.41052
B31: 3 | C31: =AVERAGE(graph_colouring!C4:L4) -> 0.006326515 | D31: =AVERAGE(graph_colouring!C105:L105) -> 0.0001605234 | E31: =(C31 - D31)/D31 -> 38.411793 | F31: =ABS(C31 - D31) / (ABS(C31 + D31) / 2) -> 1.901019 | H31: 3-col 0002.out | I31: 6 | J31: 1.8824162 | L31: 3-col 0002.out | M31: 6 | N31: 32.01829
B32: 4 | C32: =AVERAGE(graph_colouring!C5:L5) -> 0.0072016728 | D32: =AVERAGE(graph_colouring!C106:L106) -> 0.0001629493 | E32: =(C32 - D32)/D32 -> 43.195789 | F32: =ABS(C32 - D32) / (ABS(C32 + D32) / 2) -> 1.9114962 | H32: 3-col 0002.out | I32: 5 | J32: 1.8858303 | L32: 3-col 0002.out | M32: 5 | N32: 33.035574
B33: 5 | C33: =AVERAGE(graph_colouring!C6:L6) -> 0.0092092184 | D33: =AVERAGE(graph_colouring!C107:L107) -> 0.0001590306 | E33: =(C33 - D33)/D33 -> 56.908468 | F33: =ABS(C33 - D33) / (ABS(C33 + D33) / 2) -> 1.932098 | H33: graph_colouring 0003.out | I33: 4 | J33: 1.8858963 | L33: graph_colouring 0003.out | M33: 4 | N33: 33.055816
B34: 6 | C34: =AVERAGE(graph_colouring!C7:L7) -> 0.0062932069 | D34: =AVERAGE(graph_colouring!C108:L108) -> 0.0001587505 | E34: =(C34 - D34)/D34 -> 38.642123 | F34: =ABS(C34 - D34) / (ABS(C34 + D34) / 2) -> 1.9015799 | H34: labyrinth 0011.out | I34: 12 | J34: 1.8866214 | L34: labyrinth 0011.out | M34: 12 | N34: 33.280029
B35: 7 | C35: =AVERAGE(graph_colouring!C8:L8) -> 0.0060840273 | D35: =AVERAGE(graph_colouring!C109:L109) -> 0.0001597768 | E35: =(C35 - D35)/D35 -> 37.07829 | F35: =ABS(C35 - D35) / (ABS(C35 + D35) / 2) -> 1.8976414 | H35: hanoi_tower 0037.out | I35: 0 | J35: 1.8890877 | L35: hanoi_tower 0037.out | M35: 0 | N35: 34.064545
B36: 8 | C36: =AVERAGE(graph_colouring!C9:L9) -> 0.0063612227 | D36: =AVERAGE(graph_colouring!C110:L110) -> 0.0001572576 | E36: =(C36 - D36)/D36 -> 39.450972 | F36: =ABS(C36 - D36) / (ABS(C36 + D36) / 2) -> 1.9035005 | H36: ladder 0013.out | I36: 0 | J36: 1.8895368 | L36: ladder 0013.out | M36: 0 | N36: 34.211147
B37: 9 | C37: =AVERAGE(graph_colouring!C10:L10) -> 0.0074487326 | D37: =AVERAGE(graph_colouring!C111:L111) -> 0.0001612697 | E37: =(C37 - D37)/D37 -> 45.188048 | F37: =ABS(C37 - D37) / (ABS(C37 + D37) / 2) -> 1.9152328 | H37: labyrinth 0051.out | I37: 6 | J37: 1.8896501 | L37: labyrinth 0051.out | M37: 6 | N37: 34.248324
B38: 10 | C38: =AVERAGE(graph_colouring!C11:L11) -> 0.0063084614 | D38: =AVERAGE(graph_colouring!C112:L112) -> 0.000159497 | E38: =(C38 - D38)/D38 -> 38.552226 | F38: =ABS(C38 - D38) / (ABS(C38 + D38) / 2) -> 1.9013618 | H38: hanoi_tower 0011.out | I38: 0 | J38: 1.8908987 | L38: hanoi_tower 0011.out | M38: 0 | N38: 34.663173
B39: 11 | C39: =AVERAGE(graph_colouring!C12:L12) -> 0.0062791652 | D39: =AVERAGE(graph_colouring!C113:L113) -> 0.0001587972 | E39: =(C39 - D39)/D39 -> 38.54204 | F39: =ABS(C39 - D39) / (ABS(C39 + D39) / 2) -> 1.901337 | H39: 3-col 0001.out | I39: 3 | J39: 1.8909973 | L39: 3-col 0001.out | M39: 3 | N39: 34.696344
B40: 12 | C40: =AVERAGE(graph_colouring!C13:L13) -> 0.0066712602 | D40: =AVERAGE(graph_colouring!C114:L114) -> 0.0001597303 | E40: =(C40 - D40)/D40 -> 40.765778 | F40: =ABS(C40 - D40) / (ABS(C40 + D40) / 2) -> 1.9064673 | H40: hanoi_tower 0010.out | I40: 0 | J40: 1.8913316 | L40: hanoi_tower 0010.out | M40: 0 | N40: 34.809234
...

Sheet 3-col
A1: 0001.out | B1: 0 | C1: 0.009713973 | D1: 0.00136312 | E1: 0.001418633 | F1: 0.001129402 | G1: 0.001032836 | H1: 0.001139199 | I1: 0.001121938 | J1: 0.00119238 | K1: 0.000981054 | L1: 0.000963327
A2: 0001.out | B2: 1 | C2: 0.000974522 | D2: 0.000982454 | E2: 0.000885421 | F2: 0.000937202 | G2: 0.000899416 | H2: 0.000924607 | I2: 0.00088962 | J2: 0.000893352 | K2: 0.000874225 | L2: 0.001064092
A3: 0001.out | B3: 2 | C3: 0.000960062 | D3: 0.000948866 | E3: 0.000882622 | F3: 0.00114573 | G3: 0.001065025 | H3: 0.001160191 | I3: 0.001147595 | J3: 0.001146196 | K3: 0.001072955 | L3: 0.00074827
A4: 0001.out | B4: 3 | C4: 0.000993649 | D4: 0.001004379 | E4: 0.000825709 | F4: 0.000737074 | G4: 0.00063491 | H4: 0.001282414 | I4: 0.000823377 | J4: 0.000777192 | K4: 0.000879357 | L4: 0.000817778
A5: 0001.out | B5: 4 | C5: 0.000669897 | D5: 0.000514552 | E5: 0.000507554 | F5: 0.000503822 | G5: 0.000792587 | H5: 0.000735674 | I5: 0.000483297 | J5: 0.000509886 | K5: 0.000752934 | L5: 0.000639575
A6: 0001.out | B6: 5 | C6: 0.00062558 | D6: 0.000533212 | E6: 0.00051735 | F6: 0.000549073 | G6: 0.000534145 | H6: 0.000598989 | I6: 0.000540676 | J6: 0.000498691 | K6: 0.000482829 | L6: 0.000427782
A7: 0001.out | B7: 6 | C7: 0.000774394 | D7: 0.000659168 | E7: 0.000755733 | F7: 0.000693688 | G7: 0.000800051 | H7: 0.000665232 | I7: 0.000501957 | J7: 0.000500091 | K7: 0.000474899 | L7: 0.000476766
A8: 0001.out | B8: 7 | C8: 0.000598056 | D8: 0.000607852 | E8: 0.000609718 | F8: 0.000446442 | G8: 0.000431981 | H8: 0.000487495 | I8: 0.000377866 | J8: 0.000426849 | K8: 0.000410989 | L8: 0.000477232
A9: 0001.out | B9: 8 | C9: 0.00062278 | D9: 0.000582195 | E9: 0.000605053 | F9: 0.000627911 | G9: 0.000585927 | H9: 0.000574264 | I9: 0.000599455 | J9: 0.000547673 | K9: 0.00042545 | L9: 0.000446443
A10: 0001.out | B10: 9 | C10: 0.000474433 | D10: 0.000358273 | E10: 0.000371802 | F10: 0.000457638 | G10: 0.000437112 | H10: 0.000378333 | I10: 0.000469768 | J10: 0.000566333 | K10: 0.00052015 | L10: 0.000564934
A11: 0002.out | B11: 0 | C11: 0.001074355 | D11: 0.000870959 | E11: 0.000871893 | F11: 0.000816379 | G11: 0.000807982 | H11: 0.000823843 | I11: 0.00070955 | J11: 0.000669897 | K11: 0.000745937 | L11: 0.000695554
A12: 0002.out | B12: 1 | C12: 0.000682026 | D12: 0.000742672 | E12: 0.000718414 | F12: 0.000689956 | G12: 0.000773927 | H12: 0.000720279 | I12: 0.000789788 | J12: 0.000664299 | K12: 0.000645173 | L12: 0.000496825
... A47: 0002.out | B47: 12 | C47: 4.9449e-05 | D47: 1.0263e-05 | E47: 1.0263e-05 | F47: 1.2596e-05 | G47: 1.2129e-05 | H47: 1.1663e-05 | I47: 1.1662e-05 | J47: 1.0263e-05 | K47: 9.33e-06 | L47: 9.33e-06

Sheet ancestor
A1: 0001.out | B1: 0 | C1: 0.009205953 | D1: 0.01416487 | E1: 0.010826581 | F1: 0.007936134 | G1: 0.007518148 | H1: 0.007519081 | I1: 0.007347408 | J1: 0.009019818 | K1: 0.008584106 | L1: 0.004556327
A2: 0002.out | B2: 0 | C2: 0.012366971 | D2: 0.012255011 | E2: 0.044916223 | F2: 0.011433034 | G2: 0.019849199 | H2: 0.019731173 | I2: 0.047410143 | J2: 0.018989901 | K2: 0.01845669 | L2: 0.015845678
A4: 0001.out | B4: 0 | C4: 0.000190333 | D4: 0.000142749 | E4: 0.000110094 | F4: 0.000108228 | G4: 0.000103097 | H4: 0.000171673 | I4: 8.5837e-05 | J4: 8.1638e-05 | K4: 7.5107e-05 | L4: 7.7439e-05
A5: 0002.out | B5: 0 | C5: 0.000264507 | D5: 0.000249579 | E5: 0.000252845 | F5: 0.000253777 | G5: 0.000253778 | H5: 0.000262174 | I5: 0.000252844 | J5: 0.000241648 | K5: 0.000174939 | L5: 0.000170274

Sheet graph_colouring
A1: 0001.out | B1: 0 | C1: 0.008624225 | D1: 0.008334527 | E1: 0.007636173 | F1: 0.026664794 | G1: 0.006569283 | H1: 0.006681244 | I1: 0.006625263 | J1: 0.006514702 | K1: 0.006555288 | L1: 0.006608935
A2: 0001.out | B2: 1 | C2: 0.007677225 | D2: 0.01031063 | E2: 0.006466652 | F2: 0.006543159 | G2: 0.007975787 | H2: 0.008648016 | I2: 0.006878108 | J2: 0.006865978 | K2: 0.0068044 | L2: 0.006570682
A3: 0001.out | B3: 2 | C3: 0.006918226 | D3: 0.023024212 | E3: 0.006628995 | F3: 0.006837521 | G3: 0.006657452 | H3: 0.00691776 | I3: 0.011929858 | J3: 0.006579546 | K3: 0.006408806 | L3: 0.006326702
A4: 0001.out | B4: 3 | C4: 0.006345361 | D4: 0.006308975 | E4: 0.006339297 | F4: 0.006293114 | G4: 0.006295446 | H4: 0.006037937 | I4: 0.006597273 | J4: 0.006332766 | K4: 0.006429798 | L4: 0.006285183
A5: 0001.out | B5: 4 | C5: 0.006559486 | D5: 0.006299178 | E5: 0.006299644 | F5: 0.006335099 | G5: 0.007667895 | H5: 0.00773787 | I5: 0.007569463 | J5: 0.007639905 | K5: 0.007698684 | L5: 0.008209504
A6: 0001.out | B6: 5 | C6: 0.008333594 | D6: 0.007745335 | E6: 0.007705682 | F6: 0.007917474 | G6: 0.007745801 | H6: 0.008078884 | I6: 0.007770526 | J6: 0.023936223 | K6: 0.006464787 | L6: 0.006393878
A7: 0001.out | B7: 6 | C7: 0.006424667 | D7: 0.006125639 | E7: 0.006361223 | F7: 0.006332766 | G7: 0.006514702 | H7: 0.006053332 | I7: 0.006556221 | J7: 0.006283784 | K7: 0.00628425 | L7: 0.005995485
A8: 0001.out | B8: 7 | C8: 0.006306642 | D8: 0.006024875 | E8: 0.006031406 | F8: 0.00602954 | G8: 0.006263257 | H8: 0.006001083 | I8: 0.006069193 | J8: 0.005991753 | K8: 0.00611491 | L8: 0.006007614
A9: 0001.out | B9: 8 | C9: 0.006258592 | D9: 0.005993152 | E9: 0.006544558 | F9: 0.006375218 | G9: 0.006413472 | H9: 0.00649091 | I9: 0.006355158 | J9: 0.006400876 | K9: 0.006332299 | L9: 0.006447992
A10: 0001.out | B10: 9 | C10: 0.006361689 | D10: 0.006316905 | E10: 0.017849771 | F10: 0.006011813 | G10: 0.00624553 | H10: 0.006344429 | I10: 0.006410672 | J10: 0.006335099 | K10: 0.006392945 | L10: 0.006218473
A11: 0001.out | B11: 10 | C11: 0.00622687 | D11: 0.006289848 | E11: 0.006257659 | F11: 0.006287982 | G11: 0.006366821 | H11: 0.006346295 | I11: 0.006305709 | J11: 0.006329501 | K11: 0.006373818 | L11: 0.006300111
A12: 0001.out | B12: 11 | C12: 0.006268389 | D12: 0.006269788 | E12: 0.006257193 | F12: 0.006280052 | G12: 0.006233867 | H12: 0.006348628 | I12: 0.006239466 | J12: 0.00644566 | K12: 0.006329501 | L12: 0.006119108
... A201: 0013.out | B201: 12 | C201: 0.000118026 | D201: 0.00011336 | E201: 0.000113826 | F201: 0.000115226 | G201: 0.000112894 | H201: 0.000115692 | I201: 0.000114293 | J201: 0.000113827 | K201: 0.000115693 | L201: 0.000113827

Sheet hanoi_tower
A1: 0001.out | B1: 0 | C1: 0.003663907 | D1: 0.003785665 | E1: 0.003626121 | F1: 0.003432989 | G1: 0.003385872 | H1: 0.003579937 | I1: 0.003602329 | J1: 0.003538418 | K1: 0.003668573 | L1: 0.003397535
A2: 0001.out | B2: 1 | C2: 0.003618657 | D2: 0.00351556 | E2: 0.003383074 | F2: 0.003400334 | G2: 0.003853307 | H2: 0.003631719 | I2: 0.003378875 | J2: 0.003435788 | K2: 0.003392403 | L2: 0.003416195
A3: 0001.out | B3: 2 | C3: 0.003713824 | D3: 0.003455847 | E3: 0.003363481 | F3: 0.003544483 | G3: 0.003402666 | H3: 0.003376543 | I3: 0.00343952 | J3: 0.003367678 | K3: 0.003388205 | L3: 0.003362547
A4: 0001.out | B4: 3 | C4: 0.003536086 | D4: 0.003389137 | E4: 0.003466111 | F4: 0.003561744 | G4: 0.003592067 | H4: 0.003502964 | I4: 0.003561744 | J4: 0.003605128 | K4: 0.00352349 | L4: 0.00358227
A5: 0001.out | B5: 4 | C5: 0.003595332 | D5: 0.003602329 | E5: 0.003573873 | F5: 0.003550548 | G5: 0.003609326 | H5: 0.003606061 | I5: 0.003576205 | J5: 0.003370945 | K5: 0.003525823 | L5: 0.003579937
A6: 0001.out | B6: 5 | C6: 0.003612592 | D6: 0.003604195 | E6: 0.003520692 | F6: 0.003542617 | G6: 0.003639649 | H6: 0.003590667 | I6: 0.003586002 | J6: 0.003481039 | K6: 0.003572473 | L6: 0.003371877
A7: 0001.out | B7: 6 | C7: 0.003650379 | D7: 0.003621923 | E7: 0.003548681 | F7: 0.003592066 | G7: 0.003585069 | H7: 0.003559411 | I7: 0.00362099 | J7: 0.00356081 | K7: 0.003592066 | L7: 0.003619123
A8: 0001.out | B8: 7 | C8: 0.003602796 | D8: 0.003614458 | E8: 0.003532821 | F8: 0.00359813 | G8: 0.003414329 | H8: 0.00336628 | I8: 0.003612593 | J8: 0.003540751 | K8: 0.003367213 | L8: 0.003367679
A9: 0001.out | B9: 8 | C9: 0.003527223 | D9: 0.003372344 | E9: 0.003380741 | F9: 0.003388672 | G9: 0.003395202 | H9: 0.003380274 | I9: 0.003663908 | J9: 0.003390537 | K9: 0.003340155 | L9: 0.003460512
A10: 0001.out | B10: 9 | C10: 0.003613992 | D10: 0.003408264 | E10: 0.003444652 | F10: 0.003430657 | G10: 0.003428324 | H10: 0.003423659 | I10: 0.003495967 | J10: 0.003554746 | K10: 0.003701228 | L10: 0.015577906
A11: 0003.out | B11: 0 | C11: 0.003824851 | D11: 0.003660175 | E11: 0.003739948 | F11: 0.003564543 | G11: 0.00353562 | H11: 0.003756742 | I11: 0.003625188 | J11: 0.003567342 | K11: 0.003737615 | L11: 0.00361959
A12: 0003.out | B12: 1 | C12: 0.003906489 | D12: 0.003812255 | E12: 0.003709158 | F12: 0.003829049 | G12: 0.003823918 | H12: 0.00382625 | I12: 0.00374368 | J12: 0.003792196 | K12: 0.003762339 | L12: 0.003812722
... A133: 0044.out | B133: 1 | C133: 9.0968e-05 | D133: 9.7966e-05 | E133: 9.0035e-05 | F133: 9.0502e-05 | G133: 8.9568e-05 | H133: 9.0035e-05 | I133: 8.9569e-05 | J133: 9.47e-05 | K133: 9.1434e-05 | L133: 9.0501e-05

Sheet keys
A1: 0001.out | B1: 0 | C1: 0.000168408 | D1: 3.9186e-05 | E1: 4.4784e-05 | F1: 4.6184e-05 | G1: 6.9043e-05 | H1: 2.6591e-05 | I1: 2.5192e-05 | J1: 2.5191e-05 | K1: 2.6124e-05 | L1: 2.6124e-05
A3: 0001.out | B3: 0 | C3: 0.000123157 | D3: 7.464e-06 | E3: 6.064e-06 | F3: 6.065e-06 | G3: 5.598e-06 | H3: 6.065e-06 | I3: 5.131e-06 | J3: 2.2392e-05 | K3: 1.5861e-05 | L3: 5.598e-06

Sheet labyrinth
A1: 0003.out | B1: 0 | C1: 0.024677962 | D1: 0.02562123 | E1: 0.026439007 | F1: 0.024360274 | G1: 0.024598657 | H1: 0.022996222 | I1: 0.022342652 | J1: 0.022344985 | K1: 0.023168361 | L1: 0.12454067
A2: 0003.out | B2: 1 | C2: 0.024216125 | D2: 0.024103231 | E2: 0.024310825 | F2: 0.024158278 | G2: 0.022634216 | H2: 0.022775566 | I2: 0.022211565 | J2: 0.02306853 | K2: 0.022770901 | L2: 0.022278742
A3: 0003.out | B3: 2 | C3: 0.022955636 | D3: 0.022720986 | E3: 0.022795159 | F3: 0.022846008 | G3: 0.022891259 | H3: 0.022191039 | I3: 0.022111267 | J3: 0.022084676 | K3: 0.022384171 | L3: 0.02242429
A4: 0003.out | B4: 3 | C4: 0.02224702 | D4: 0.02290432 | E4: 0.022984093 | F4: 0.030828792 | G4: 0.022305798 | H4: 0.022456012 | I4: 0.022719119 | J4: 0.022102404 | K4: 0.022097738 | L4: 0.022259615
A5: 0003.out | B5: 4 | C5: 0.0228712 | D5: 0.022334721 | E5: 0.022704191 | F5: 0.023094187 | G5: 0.022844142 | H5: 0.022420558 | I5: 0.022169114 | J5: 0.022615556 | K5: 0.022814752 | L5: 0.022752708
A6: 0003.out | B6: 5 | C6: 0.022448082 | D6: 0.023047537 | E6: 0.022276876 | F6: 0.02266034 | G6: 0.022852539 | H6: 0.022801691 | I6: 0.030253596 | J6: 0.022622553 | K6: 0.023363359 | L6: 0.023124043
A7: 0003.out | B7: 6 | C7: 0.024052383 | D7: 0.023066197 | E7: 0.022356648 | F7: 0.022619754 | G7: 0.022969165 | H7: 0.022378573 | I7: 0.022387437 | J7: 0.022110334 | K7: 0.022936509 | L7: 0.023061066
A8: 0003.out | B8: 7 | C8: 0.022959368 | D8: 0.022967299 | E8: 0.022365045 | F8: 0.022442484 | G8: 0.022235823 | H8: 0.022549313 | I8: 0.022041758 | J8: 0.022355714 | K8: 0.022080011 | L8: 0.027441521
A9: 0003.out | B9: 8 | C9: 0.022962167 | D9: 0.023034475 | E9: 0.022275476 | F9: 0.022713055 | G9: 0.022744311 | H9: 0.024323421 | I9: 0.02365399 | J9: 0.022156985 | K9: 0.022159317 | L9: 0.023285453
A10: 0003.out | B10: 9 | C10: 0.022598295 | D10: 0.02263235 | E10: 0.02208561 | F10: 0.022988758 | G10: 0.023620868 | H10: 0.023202883 | I10: 0.023498645 | J10: 0.034148422 | K10: 0.02364326 | L10: 0.022920182
A11: 0003.out | B11: 10 | C11: 0.022518991 | D11: 0.022850674 | E11: 0.02723486 | F11: 0.022351516 | G11: 0.022302533 | H11: 0.022808221 | I11: 0.023073195 | J11: 0.022463009 | K11: 0.022337054 | L11: 0.022401899
A12: 0003.out | B12: 11 | C12: 0.022697661 | D12: 0.022213431 | E12: 0.022110334 | F12: 0.022347784 | G12: 0.037409271 | H12: 0.023208947 | I12: 0.023235538 | J12: 0.022884261 | K12: 0.022488667 | L12: 0.022176111
... A647: 0175.out | B647: 21 | C647: 0.000396993 | D647: 0.000408656 | E647: 0.008715192 | F647: 0.00042545 | G647: 0.000410522 | H647: 0.000410522 | I647: 0.000382532 | J647: 0.000382999 | K647: 0.000380666 | L647: 0.000382998

Sheet ladder
A1: 0001.out | B1: 0 | C1: 0.002729504 | D1: 0.002718308 | E1: 0.002577891 | F1: 0.002736968 | G1: 0.002621742 | H1: 0.002613345 | I1: 0.002777088 | J1: 0.002632938 | K1: 0.002559697 | L1: 0.002565762
A2: 0002.out | B2: 0 | C2: 0.000285965 | D2: 0.000279435 | E2: 0.000280834 | F2: 0.000285499 | G2: 0.000285499 | H2: 0.000281767 | I2: 0.000284566 | J2: 0.000278969 | K2: 0.0002841 | L2: 0.000284566
A3: 0003.out | B3: 0 | C3: 0.002766824 | D3: 0.002820938 | E3: 0.002761692 | F3: 0.002770556 | G3: 0.002768223 | H3: 0.00274863 | I3: 0.002669792 | J3: 0.002651131 | K3: 0.002758894 | L3: 0.002752362
A4: 0004.out | B4: 0 | C4: 0.003101772 | D4: 0.003291639 | E4: 0.003264116 | F4: 0.00327158 | G4: 0.003217465 | H4: 0.003181545 | I4: 0.003151221 | J4: 0.00320347 | K4: 0.003056522 | L4: 0.003048125
A5: 0005.out | B5: 0 | C5: 0.003328959 | D5: 0.00335555 | E5: 0.003321961 | F5: 0.00337561 | G5: 0.00331683 | H5: 0.003390537 | I5: 0.003631252 | J5: 0.003599997 | K5: 0.003674637 | L5: 0.003653178
A6: 0006.out | B6: 0 | C6: 0.003905089 | D6: 0.003807123 | E6: 0.003777268 | F6: 0.008826687 | G6: 0.003790796 | H6: 0.003908821 | I6: 0.004972913 | J6: 0.005101667 | K6: 0.003744146 | L6: 0.003795461
A7: 0007.out | B7: 0 | C7: 0.003982995 | D7: 0.003986727 | E7: 0.003989992 | F7: 0.003908821 | G7: 0.003868702 | H7: 0.004343601 | I7: 0.003922816 | J7: 0.003880364 | K7: 0.003867769 | L7: 0.003851442
A8: 0008.out | B8: 0 | C8: 0.004191055 | D8: 0.004093556 | E8: 0.004162132 | F8: 0.004221378 | G8: 0.004174261 | H8: 0.004184058 | I8: 0.004190122 | J8: 0.004158866 | K8: 0.004181725 | L8: 0.004177527
A9: 0009.out | B9: 0 | C9: 0.004481219 | D9: 0.004632367 | E9: 0.00470654 | F9: 0.00482783 | G9: 0.004755989 | H9: 0.004635631 | I9: 0.004697677 | J9: 0.004636098 | K9: 0.00506388 | L9: 0.005031692
A10: 0010.out | B10: 0 | C10: 0.004744793 | D10: 0.004725666 | E10: 0.004763453 | F10: 0.004790977 | G10: 0.004683215 | H10: 0.004765786 | I10: 0.004744326 | J10: 0.004680416 | K10: 0.004802172 | L10: 0.004700941
A11: 0011.out | B11: 0 | C11: 0.004932794 | D11: 0.004678083 | E11: 0.004755523 | F11: 0.004870282 | G11: 0.0047252 | H11: 0.005175841 | I11: 0.004710272 | J11: 0.004987841 | K11: 0.004775115 | L11: 0.004804038
A12: 0012.out | B12: 0 | C12: 0.005741708 | D12: 0.005745907 | E12: 0.005653539 | F12: 0.005579832 | G12: 0.005479068 | H12: 0.005350779 | I12: 0.005285935 | J12: 0.005474402 | K12: 0.005303663 | L12: 0.005259812
... A41: 0020.out | B41: 0 | C41: 6.0645e-05 | D41: 6.0179e-05 | E41: 5.878e-05 | F41: 5.8779e-05 | G41: 5.8313e-05 | H41: 5.8779e-05 | I41: 5.8779e-05 | J41: 5.8779e-05 | K41: 5.8779e-05 | L41: 5.8779e-05

Sheet network
A1: 0001.out | B1: 0 | C1: 0.000242114 | D1: 0.00021739 | E1: 0.000195464 | F1: 0.000189867 | G1: 0.000190799 | H1: 0.000208526 | I1: 0.000227653 | J1: 0.000193598 | K1: 0.000231385 | L1: 0.000200129
A3: 0001.out | B3: 0 | C3: 2.333e-06 | D3: 1.866e-06 | E3: 1.866e-06 | F3: 1.866e-06 | G3: 1.866e-06 | H3: 1.866e-06 | I3: 1.866e-06 | J3: 1.866e-06 | K3: 1.866e-06 | L3: 1.866e-06

Sheet stable_marriage
A1: 0001.out | B1: 0 | C1: 0.23310364 | D1: 0.25952679 | E1: 0.26381348 | F1: 0.26173614 | G1: 0.24718967 | H1: 0.22577816 | I1: 0.21142856 | J1: 0.22072501 | K1: 0.2267928 | L1: 0.23111728
A2: 0001.out | B2: 1 | C2: 0.26008846 | D2: 0.22819558 | E2: 0.24776021 | F2: 0.25876406 | G2: 0.26963356 | H2: 0.22390469 | I2: 0.26045233 | J2: 0.2625166 | K2: 0.25433555 | L2: 0.22442857
A3: 0001.out | B3: 2 | C3: 0.25174693 | D3: 0.25369971 | E3: 0.21017366 | F3: 0.24401419 | G3: 0.24781712 | H3: 0.22488201 | I3: 0.26041734 | J3: 0.26889649 | K3: 0.22618075 | L3: 0.24646753
A4: 0001.out | B4: 3 | C4: 0.25286934 | D4: 0.21372048 | E4: 0.21713108 | F4: 0.24695409 | G4: 0.20549558 | H4: 0.22417246 | I4: 0.19099483 | J4: 0.2768051 | K4: 0.25682994 | L4: 0.24052009
A5: 0001.out | B5: 4 | C5: 0.27863565 | D5: 0.22237409 | E5: 0.22245573 | F5: 0.23397554 | G5: 0.20965118 | H5: 0.22932637 | I5: 0.21555523 | J5: 0.23503589 | K5: 0.23475646 | L5: 0.21236296
A6: 0001.out | B6: 5 | C6: 0.23044318 | D6: 0.22871153 | E6: 0.24194572 | F6: 0.23998362 | G6: 0.2736786 | H6: 0.21821243 | I6: 0.26173801 | J6: 0.26235099 | K6: 0.25510342 | L6: 0.27329327
A7: 0001.out | B7: 6 | C7: 0.2302869 | D7: 0.26056989 | E7: 0.23651471 | F7: 0.27641137 | G7: 0.23676429 | H7: 0.27951967 | I7: 0.26323875 | J7: 0.26812629 | K7: 0.21323952 | L7: 0.25220364
A8: 0001.out | B8: 7 | C8: 0.24005452 | D8: 0.26093143 | E8: 0.22966226 | F8: 0.26240091 | G8: 0.22165428 | H8: 0.26520039 | I8: 0.22517171 | J8: 0.27162319 | K8: 0.23890273 | L8: 0.27128358
A9: 0001.out | B9: 8 | C9: 0.23895265 | D9: 0.2573193 | E9: 0.236267 | F9: 0.24217244 | G9: 0.2307576 | H9: 0.26163305 | I9: 0.24102205 | J9: 0.23787269 | K9: 0.22117238 | L9: 0.25591653
A10: 0001.out | B10: 9 | C10: 0.23030416 | D10: 0.2192518 | E10: 0.19455611 | F10: 0.21637068 | G10: 0.19672208 | H10: 0.19624858 | I10: 0.21991703 | J10: 0.20963206 | K10: 0.23254991 | L10: 0.2125295
A11: 0001.out | B11: 10 | C11: 0.22653109 | D11: 0.20298767 | E11: 0.24177918 | F11: 0.21150459 | G11: 0.23839844 | H11: 0.20692261 | I11: 0.24773408 | J11: 0.29746694 | K11: 0.24082705 | L11: 0.30408707
A12: 0001.out | B12: 11 | C12: 0.28302543 | D12: 0.30671301 | E12: 0.2570338 | F12: 0.2963534 | G12: 0.28375831 | H12: 0.29049273 | I12: 0.28817142 | J12: 0.24799579 | K12: 0.26750584 | L12: 0.23957683
... A341: 0026.out | B341: 10 | C341: 0.001014175 | D341: 0.001017908 | E341: 0.00099085 | F341: 0.000990384 | G341: 0.001007178 | H341: 0.000988052 | I341: 0.00099085 | J341: 0.000989451 | K341: 0.000989918 | L341: 0.000990384
