Workbook
Name _3_col: '3-col'!$A$1:$L$19
Name ancestor: ancestor!$A$1:$L$19
Name graph_colouring: graph_colouring!$A$1:$L$31
Name hanoi_tower: hanoi_tower!$A$1:$L$67
Name keys: keys!$A$1:$L$13
Name labyrinth: labyrinth!$A$1:$L$79
Name ladder: ladder!$A$1:$L$127
Name maximal_clique_problem: maximal_clique_problem!$A$1:$L$71
Name network: network!$A$1:$L$13
Name stable_marriage: stable_marriage!$A$1:$L$75
Name visit_all: visit_all!$A$1:$L$51

Sheet refined_data
A1: ASP SOLVERS | C1: Clingo | E1: DLV | G1: DLV2
C2: NEW | D2: OLD | E2: NEW | F2: OLD | G2: NEW | H2: OLD
A3: 3-col 0001.out | C3: =AVERAGE('3-col'!B2:K2) -> 0.018927805 | D3: =AVERAGE('3-col'!B12:K12) -> 0.0013736155 | E3: =AVERAGE('3-col'!B5:K5) -> 0.017167591 | F3: =AVERAGE('3-col'!B15:K15) -> 0.0005842473 | G3: =AVERAGE('3-col'!B8:K8) -> 0.0066999347 | H3: NO_RESULT
A4: 3-col 0002.out | C4: =AVERAGE('3-col'!B3:K3) -> 0.008760484 | D4: =AVERAGE('3-col'!B13:K13) -> 0.00105826 | E4: =AVERAGE('3-col'!B6:K6) -> 0.0074419563 | F4: =AVERAGE('3-col'!B16:K16) -> 0.0006425602 | G4: =AVERAGE('3-col'!B9:K9) -> 0.0065145458 | H4: NO_RESULT
A5: ancestor 0001.out | C5: =AVERAGE(ancestor!B2:K2) -> 0.016057124 | D5: =AVERAGE(ancestor!B12:K12) -> 0.000568013 | E5: =AVERAGE(ancestor!B5:K5) -> 0.0039338907 | F5: =AVERAGE(ancestor!B15:K15) -> 0.0005333049 | G5: =AVERAGE(ancestor!B8:K8) -> 0.0046815571 | H5: NO_RESULT
A6: ancestor 0002.out | C6: =AVERAGE(ancestor!B3:K3) -> 0.01881813 | D6: =AVERAGE(ancestor!B13:K13) -> 0.0007482694 | E6: =AVERAGE(ancestor!B6:K6) -> 0.014845986 | F6: =AVERAGE(ancestor!B16:K16) -> 0.0010110035 | G6: =AVERAGE(ancestor!B9:K9) -> 0.014581991 | H6: NO_RESULT
A7: graph_colouring 0001.out | C7: =AVERAGE(graph_colouring!B2:K2) -> 0.22890157 | D7: =AVERAGE(graph_colouring!B18:K18) -> 0.028275626 | G7: =AVERAGE(graph_colouring!B10:K10) -> 0.19700486 | H7: NO_RESULT
A8: graph_colouring 0003.out | C8: =AVERAGE(graph_colouring!B3:K3) -> 0.067830144 | D8: =AVERAGE(graph_colouring!B19:K19) -> 0.009615215 | G8: =AVERAGE(graph_colouring!B11:K11) -> 0.061277018 | H8: NO_RESULT
A9: graph_colouring 0007.out | C9: =AVERAGE(graph_colouring!B4:K4) -> 0.26932109 | D9: =AVERAGE(graph_colouring!B20:K20) -> 0.037476494 | G9: =AVERAGE(graph_colouring!B12:K12) -> 0.23363916 | H9: NO_RESULT
A10: graph_colouring 0009.out | C10: =AVERAGE(graph_colouring!B5:K5) -> 0.13518879 | D10: =AVERAGE(graph_colouring!B21:K21) -> 0.021830666 | G10: =AVERAGE(graph_colouring!B13:K13) -> 0.14953058 | H10: NO_RESULT
A11: graph_colouring 0010.out | C11: =AVERAGE(graph_colouring!B6:K6) -> 0.075385321 | D11: =AVERAGE(graph_colouring!B22:K22) -> 0.01134981 | G11: =AVERAGE(graph_colouring!B14:K14) -> 0.08277083 | H11: NO_RESULT
A12: graph_colouring 0013.out | C12: =AVERAGE(graph_colouring!B7:K7) -> 0.10982943 | D12: =AVERAGE(graph_colouring!B23:K23) -> 0.015899652 | G12: =AVERAGE(graph_colouring!B15:K15) -> 0.10438789 | H12: NO_RESULT
A13: hanoi_tower 0001.out | C13: =AVERAGE(hanoi_tower!B2:K2) -> 0.043088809 | D13: =AVERAGE(hanoi_tower!B36:K36) -> 0.0092753219 | G13: =AVERAGE(hanoi_tower!B19:K19) -> 0.047118566 | H13: NO_RESULT
A14: hanoi_tower 0003.out | C14: =AVERAGE(hanoi_tower!B3:K3) -> 0.066197939 | D14: =AVERAGE(hanoi_tower!B37:K37) -> 0.013437127 | G14: =AVERAGE(hanoi_tower!B20:K20) -> 0.076187568 | H14: NO_RESULT
A15: hanoi_tower 0009.out | C15: =AVERAGE(hanoi_tower!B4:K4) -> 0.0036788062 | D15: =AVERAGE(hanoi_tower!B38:K38) -> 0.0008016837 | G15: =AVERAGE(hanoi_tower!B21:K21) -> 0.004283349 | H15: NO_RESULT
A16: hanoi_tower 0010.out | C16: =AVERAGE(hanoi_tower!B5:K5) -> 0.0037385188 | D16: =AVERAGE(hanoi_tower!B39:K39) -> 0.0008803829 | G16: =AVERAGE(hanoi_tower!B22:K22) -> 0.0042069826 | H16: NO_RESULT
A17: hanoi_tower 0011.out | C17: =AVERAGE(hanoi_tower!B6:K6) -> 0.0042696807 | D17: =AVERAGE(hanoi_tower!B40:K40) -> 0.0008502933 | G17: =AVERAGE(hanoi_tower!B23:K23) -> 0.004420035 | H17: NO_RESULT
A18: hanoi_tower 0024.out | C18: =AVERAGE(hanoi_tower!B7:K7) -> 0.07572223 | D18: =AVERAGE(hanoi_tower!B41:K41) -> 0.014994731 | G18: =AVERAGE(hanoi_tower!B24:K24) -> 0.074852433 | H18: NO_RESULT
A19: hanoi_tower 0029.out | C19: =AVERAGE(hanoi_tower!B8:K8) -> 0.013249842 | D19: =AVERAGE(hanoi_tower!B42:K42) -> 0.0025652953 | G19: =AVERAGE(hanoi_tower!B25:K25) -> 0.012682246 | H19: NO_RESULT
A20: hanoi_tower 0030.out | C20: =AVERAGE(hanoi_tower!B9:K9) -> 0.013399636 | D20: =AVERAGE(hanoi_tower!B43:K43) -> 0.0026875187 | G20: =AVERAGE(hanoi_tower!B26:K26) -> 0.013609516 | H20: NO_RESULT
A21: hanoi_tower 0031.out | C21: =AVERAGE(hanoi_tower!B10:K10) -> 0.013932757 | D21: =AVERAGE(hanoi_tower!B44:K44) -> 0.0028448232 | G21: =AVERAGE(hanoi_tower!B27:K27) -> 0.013633588 | H21: NO_RESULT
A22: hanoi_tower 0035.out | C22: =AVERAGE(hanoi_tower!B11:K11) -> 0.014505531 | D22: =AVERAGE(hanoi_tower!B45:K45) -> 0.0031147413 | G22: =AVERAGE(hanoi_tower!B28:K28) -> 0.015530721 | H22: NO_RESULT
A23: hanoi_tower 0037.out | C23: =AVERAGE(hanoi_tower!B12:K12) -> 0.0041658367 | D23: =AVERAGE(hanoi_tower!B46:K46) -> 0.0010060584 | G23: =AVERAGE(hanoi_tower!B29:K29) -> 0.0044998071 | H23: NO_RESULT
A24: hanoi_tower 0039.out | C24: =AVERAGE(hanoi_tower!B13:K13) -> 0.004439255 | D24: =AVERAGE(hanoi_tower!B47:K47) -> 0.0009750829 | G24: =AVERAGE(hanoi_tower!B30:K30) -> 0.0048034546 | H24: NO_RESULT
... A27: hanoi_tower 0044.out | C27: =AVERAGE(hanoi_tower!B16:K16) -> 0.0085024139 | D27: =AVERAGE(hanoi_tower!B50:K50) -> 0.0018032171 | G27: =AVERAGE(hanoi_tower!B33:K33) -> 0.0087599243 | H27: NO_RESULT
A28: keys 0001.out | C28: =AVERAGE(keys!B2:K2) -> 5.68203e-05 | D28: =AVERAGE(keys!B9:K9) -> 8.0285e-05 | E28: =AVERAGE(keys!B4:K4) -> 7.85595e-05 | F28: =AVERAGE(keys!B11:K11) -> 4.777e-05 | G28: =AVERAGE(keys!B6:K6) -> 5.12688e-05 | H28: NO_RESULT
A29: labyrinth 0003.out | C29: =AVERAGE(labyrinth!B2:K2) -> 0.80770917 | D29: =AVERAGE(labyrinth!B42:K42) -> 0.046272112 | G29: =AVERAGE(labyrinth!B22:K22) -> 0.72218741 | H29: NO_RESULT
A30: labyrinth 0011.out | C30: =AVERAGE(labyrinth!B3:K3) -> 1.3618497 | D30: =AVERAGE(labyrinth!B43:K43) -> 0.065004317 | G30: =AVERAGE(labyrinth!B23:K23) -> 1.5474636 | H30: NO_RESULT
A31: labyrinth 0018.out | C31: =AVERAGE(labyrinth!B4:K4) -> 0.45935022 | D31: =AVERAGE(labyrinth!B44:K44) -> 0.030516563 | G31: =AVERAGE(labyrinth!B24:K24) -> 0.59336892 | H31: NO_RESULT
A32: labyrinth 0028.out | C32: =AVERAGE(labyrinth!B5:K5) -> 0.38967122 | D32: =AVERAGE(labyrinth!B45:K45) -> 0.027472869 | G32: =AVERAGE(labyrinth!B25:K25) -> 0.46556438 | H32: NO_RESULT
A33: labyrinth 0036.out | C33: =AVERAGE(labyrinth!B6:K6) -> 3.9878222 | D33: =AVERAGE(labyrinth!B46:K46) -> 0.16519218 | G33: =AVERAGE(labyrinth!B26:K26) -> 4.3097917 | H33: NO_RESULT
A34: labyrinth 0043.out | C34: =AVERAGE(labyrinth!B7:K7) -> 0.42984242 | D34: =AVERAGE(labyrinth!B47:K47) -> 0.032177077 | G34: =AVERAGE(labyrinth!B27:K27) -> 0.51449405 | H34: NO_RESULT
A35: labyrinth 0051.out | C35: =AVERAGE(labyrinth!B8:K8) -> 1.5617589 | D35: =AVERAGE(labyrinth!B48:K48) -> 0.085784048 | G35: =AVERAGE(labyrinth!B28:K28) -> 1.8050574 | H35: NO_RESULT
A36: labyrinth 0059.out | C36: =AVERAGE(labyrinth!B9:K9) -> 1.1878818 | D36: =AVERAGE(labyrinth!B49:K49) -> 0.068413748 | G36: =AVERAGE(labyrinth!B29:K29) -> 1.4815532 | H36: NO_RESULT
A37: labyrinth 0067.out | C37: =AVERAGE(labyrinth!B10:K10) -> 0.69108445 | D37: =AVERAGE(labyrinth!B50:K50) -> 0.04519827 | G37: =AVERAGE(labyrinth!B30:K30) -> 0.8569619 | H37: NO_RESULT
A38: labyrinth 0075.out | C38: =AVERAGE(labyrinth!B11:K11) -> 1.9188925 | D38: =AVERAGE(labyrinth!B51:K51) -> 0.097440396 | G38: =AVERAGE(labyrinth!B31:K31) -> 2.2300564 | H38: NO_RESULT
A39: labyrinth 0092.out | C39: =AVERAGE(labyrinth!B12:K12) -> 2.2769547 | D39: =AVERAGE(labyrinth!B52:K52) -> 0.11929756 | G39: =AVERAGE(labyrinth!B32:K32) -> 2.7404234 | H39: NO_RESULT
A40: labyrinth 0100.out | C40: =AVERAGE(labyrinth!B13:K13) -> 0.32005889 | D40: =AVERAGE(labyrinth!B53:K53) -> 0.023105337 | G40: =AVERAGE(labyrinth!B33:K33) -> 0.40790016 | H40: NO_RESULT
... A46: labyrinth 0175.out | C46: =AVERAGE(labyrinth!B19:K19) -> 2.6676476 | D46: =AVERAGE(labyrinth!B59:K59) -> 0.10987333 | G46: =AVERAGE(labyrinth!B39:K39) -> 2.8122666 | H46: NO_RESULT
A47: ladder 0001.out | C47: =AVERAGE(ladder!B2:K2) -> 0.0031810461 | D47: =AVERAGE(ladder!B66:K66) -> 0.000743558 | E47: =AVERAGE(ladder!B23:K23) -> 0.0034917381 | F47: =AVERAGE(ladder!B87:K87) -> 0.0009613207 | G47: =AVERAGE(ladder!B44:K44) -> 0.0030103519 | H47: NO_RESULT
...

Sheet 3-col
A1: clingo
A2: 0001.out | B2: 0.11354155 | C2: 0.018384934 | D2: 0.013093376 | E2: 0.010422639 | F2: 0.007771495 | G2: 0.007249476 | H2: 0.004125297 | I2: 0.005723075 | J2: 0.005550934 | K2: 0.003415278
A3: 0002.out | B3: 0.018297231 | C3: 0.012349302 | D3: 0.011696662 | E3: 0.010722134 | F3: 0.006645354 | G3: 0.007010626 | H3: 0.006313669 | I3: 0.005055507 | J3: 0.004763475 | K3: 0.00475088
A4: dlv
A5: 0001.out | B5: 0.10876268 | C5: 0.009189668 | D5: 0.006618297 | E5: 0.006314603 | F5: 0.004430858 | G5: 0.009949603 | H5: 0.006735389 | I5: 0.006806764 | J5: 0.006725126 | K5: 0.006142928
A6: 0002.out | B6: 0.00940426 | C6: 0.0094803 | D6: 0.008857051 | E6: 0.008816464 | F6: 0.009127157 | G6: 0.006831489 | H6: 0.00541005 | I6: 0.005469762 | J6: 0.005545336 | K6: 0.005477694
A7: dlv2
A8: 0001.out | B8: 0.019818968 | C8: 0.00763481 | D8: 0.006735855 | E8: 0.006682208 | F8: 0.004068851 | G8: 0.004130895 | H8: 0.003977416 | I8: 0.003219812 | J8: 0.005090495 | K8: 0.005640037
A9: 0002.out | B9: 0.011153185 | C9: 0.00821794 | D9: 0.006646286 | E9: 0.006666347 | F9: 0.006480678 | G9: 0.008367221 | H9: 0.004591801 | I9: 0.004595534 | J9: 0.004398202 | K9: 0.004028264
A11: OLDclingo
A12: 0001.out | B12: 0.005396497 | C12: 0.001883735 | D12: 0.001375249 | E12: 0.000849033 | F12: 0.000735674 | G12: 0.000839704 | H12: 0.000753401 | I12: 0.000642373 | J12: 0.000663833 | K12: 0.000596656
A13: 0002.out | B13: 0.001371049 | C13: 0.0009456 | D13: 0.001309938 | E13: 0.001101878 | F13: 0.001032836 | G13: 0.000852766 | H13: 0.000759932 | I13: 0.000732408 | J13: 0.001231566 | K13: 0.001244627
A14: OLDdlv
A15: 0001.out | B15: 0.000854632 | C15: 0.000561202 | D15: 0.000515019 | E15: 0.000831773 | F15: 0.000563068 | G15: 0.000535544 | H15: 0.0005668 | I15: 0.000485162 | J15: 0.000485163 | K15: 0.00044411
A16: 0002.out | B16: 0.000853698 | C16: 0.000819178 | D16: 0.00050289 | E16: 0.000492626 | F16: 0.000514086 | G16: 0.000463703 | H16: 0.000490294 | I16: 0.000752468 | J16: 0.000773461 | K16: 0.000763198
A17: OLDdlv2
A18: 0001.out | B18: 9.3767e-05 | C18: 4.1052e-05 | D18: 3.8253e-05 | E18: 3.2656e-05 | F18: 2.6124e-05 | G18: 4.1053e-05 | H18: 2.799e-05 | I18: 2.7524e-05 | J18: 2.7058e-05 | K18: 2.7523e-05
A19: 0002.out | B19: 3.9653e-05 | C19: 3.5454e-05 | D19: 3.8719e-05 | E19: 5.3181e-05 | F19: 3.3588e-05 | G19: 3.3121e-05 | H19: 2.7524e-05 | I19: 2.8923e-05 | J19: 2.7057e-05 | K19: 2.5191e-05

Sheet ancestor
A1: clingo
A2: 0001.out | B2: 0.012060536 | C2: 0.010703008 | D2: 0.009317956 | E2: 0.005938133 | F2: 0.009697691 | G2: 0.009261976 | H2: 0.010378321 | I2: 0.075558301 | J2: 0.00817922 | K2: 0.009476101
A3: 0002.out | B3: 0.023621911 | C3: 0.021188624 | D3: 0.031129365 | E3: 0.020473008 | F3: 0.012831667 | G3: 0.012274661 | H3: 0.018721284 | I3: 0.014527411 | J3: 0.014806379 | K3: 0.018606991
A4: dlv
A5: 0001.out | B5: 0.004398669 | C5: 0.003665325 | D5: 0.005223448 | E5: 0.004282043 | F5: 0.004176613 | G5: 0.003670456 | H5: 0.003511844 | I5: 0.003501581 | J5: 0.003471258 | K5: 0.00343767
A6: 0002.out | B6: 0.019738263 | C6: 0.014976187 | D6: 0.032253174 | E6: 0.01511194 | F6: 0.010889143 | G6: 0.010874681 | H6: 0.01096425 | I6: 0.010780914 | J6: 0.010784646 | K6: 0.01208666
A7: dlv2
A8: 0001.out | B8: 0.004797531 | C8: 0.00455728 | D8: 0.004345021 | E8: 0.004528357 | F8: 0.00466411 | G8: 0.006514266 | H8: 0.004423393 | I8: 0.004284375 | J8: 0.004401002 | K8: 0.004300236
A9: 0002.out | B9: 0.014772791 | C9: 0.021347702 | D9: 0.015885404 | E9: 0.011709724 | F9: 0.013358817 | G9: 0.011244153 | H9: 0.011409762 | I9: 0.011095805 | J9: 0.017425801 | K9: 0.017569951
A11: OLDclingo
A12: 0001.out | B12: 0.00065357 | C12: 0.000646572 | D12: 0.000756667 | E12: 0.000633044 | F12: 0.000714214 | G12: 0.00061345 | H12: 0.000631644 | I12: 0.000346144 | J12: 0.000341013 | K12: 0.000343812
A13: 0002.out | B13: 0.000799118 | C13: 0.000761332 | D13: 0.000779992 | E13: 0.000745937 | F13: 0.000720746 | G13: 0.00074687 | H13: 0.000729143 | I13: 0.000724944 | J13: 0.000747802 | K13: 0.00072681
A14: OLDdlv
A15: 0001.out | B15: 0.000379266 | C15: 0.000485162 | D15: 0.000629778 | E15: 0.000617182 | F15: 0.00059479 | G15: 0.00059339 | H15: 0.000598988 | I15: 0.00059479 | J15: 0.000552338 | K15: 0.000287365
A16: 0002.out | B16: 0.001303873 | C16: 0.001378981 | D16: 0.001299675 | E16: 0.001268886 | F16: 0.001083685 | G16: 0.000758532 | H16: 0.000750135 | I16: 0.00074827 | J16: 0.000759932 | K16: 0.000758066
A17: OLDdlv2
A18: 0001.out | B18: 5.4114e-05 | C18: 3.8253e-05 | D18: 3.8253e-05 | E18: 4.5718e-05 | F18: 3.6388e-05 | G18: 3.732e-05 | H18: 2.9856e-05 | I18: 2.7524e-05 | J18: 2.7057e-05 | K18: 2.6591e-05
A19: 0002.out | B19: 7.1375e-05 | C19: 6.2511e-05 | D19: 6.1112e-05 | E19: 5.8779e-05 | F19: 5.8779e-05 | G19: 6.2512e-05 | H19: 6.0645e-05 | I19: 6.0179e-05 | J19: 6.2978e-05 | K19: 5.8779e-05

Sheet graph_colouring
A1: clingo
A2: 0001.out | B2: 0.28788913 | C2: 0.45275081 | D2: 0.17441243 | E2: 0.18744749 | F2: 0.19141278 | G2: 0.21934892 | H2: 0.1741913 | I2: 0.2042827 | J2: 0.18436903 | K2: 0.21291116
A3: 0003.out | B3: 0.059678028 | C3: 0.061630815 | D3: 0.060011113 | E3: 0.060133803 | F3: 0.059497491 | G3: 0.059162075 | H3: 0.13873511 | I3: 0.060569051 | J3: 0.05953621 | K3: 0.059347743
A4: 0007.out | B4: 0.21326384 | C4: 0.28517781 | D4: 0.21763825 | E4: 0.22560427 | F4: 0.2953392 | G4: 0.21975524 | H4: 0.55494698 | I4: 0.21942169 | J4: 0.21534538 | K4: 0.24671826
A5: 0009.out | B5: 0.12773167 | C5: 0.13145858 | D5: 0.12929166 | E5: 0.16549007 | F5: 0.12807549 | G5: 0.12799711 | H5: 0.12673149 | I5: 0.15037393 | J5: 0.13007119 | K5: 0.13466673
A6: 0010.out | B6: 0.081353683 | C6: 0.073141342 | D6: 0.073878885 | E6: 0.077219523 | F6: 0.072707493 | G6: 0.073765058 | H6: 0.073178196 | I6: 0.072202735 | J6: 0.080024613 | K6: 0.076381681
A7: 0013.out | B7: 0.13443441 | C7: 0.10851636 | D7: 0.10665781 | E7: 0.10091188 | F7: 0.10279422 | G7: 0.12324857 | H7: 0.10304567 | I7: 0.11438965 | J7: 0.1012137 | K7: 0.10308205
A8: dlv
A9: dlv2
A10: 0001.out | B10: 0.22648317 | C10: 0.18043873 | D10: 0.17846495 | E10: 0.21349709 | F10: 0.18029831 | G10: 0.17748529 | H10: 0.21391834 | I10: 0.19442733 | J10: 0.18798957 | K10: 0.21704579
A11: 0003.out | B11: 0.059970993 | C11: 0.060455225 | D11: 0.060396911 | E11: 0.059690157 | F11: 0.061115795 | G11: 0.061378436 | H11: 0.060468753 | I11: 0.060135668 | J11: 0.067958479 | K11: 0.061199765
A12: 0007.out | B12: 0.22511491 | C12: 0.26044701 | D12: 0.21922716 | E12: 0.21898831 | F12: 0.23578386 | G12: 0.22101341 | H12: 0.2561841 | I12: 0.21774461 | J12: 0.26111458 | K12: 0.22077362
A13: 0009.out | B13: 0.13017942 | C13: 0.15347245 | D13: 0.1281464 | E13: 0.12753621 | F13: 0.1292007 | G13: 0.15940918 | H13: 0.13423288 | I13: 0.13231228 | J13: 0.14564357 | K13: 0.25517272
A14: 0010.out | B14: 0.080323175 | C14: 0.084130783 | D14: 0.12615209 | E14: 0.082056706 | F14: 0.078676882 | G14: 0.075672594 | H14: 0.078082555 | I14: 0.074144793 | J14: 0.074438224 | K14: 0.0740305
A15: 0013.out | B15: 0.10385785 | C15: 0.10329945 | D15: 0.10703195 | E15: 0.10686354 | F15: 0.10424085 | G15: 0.10359567 | H15: 0.10167554 | I15: 0.10982164 | J15: 0.10084843 | K15: 0.10264401
A17: OLDclingo
A18: 0001.out | B18: 0.035797506 | C18: 0.028400649 | D18: 0.027953274 | E18: 0.027662176 | F18: 0.02732956 | G18: 0.02984494 | H18: 0.027069718 | I18: 0.02606394 | J18: 0.026176833 | K18: 0.026457668
A19: 0003.out | B19: 0.009295521 | C19: 0.009193358 | D19: 0.010822849 | E19: 0.009483988 | F19: 0.009774619 | G19: 0.009079064 | H19: 0.009317447 | I19: 0.009641199 | J19: 0.009887045 | K19: 0.00965706
A20: 0007.out | B20: 0.035008184 | C20: 0.048680895 | D20: 0.050827272 | E20: 0.034702626 | F20: 0.033617542 | G20: 0.03329239 | H20: 0.033522375 | I20: 0.03786551 | J20: 0.033339506 | K20: 0.033908639
A21: 0009.out | B21: 0.021117618 | C21: 0.021575723 | D21: 0.021325211 | E21: 0.021983446 | F21: 0.022358047 | G21: 0.021938662 | H21: 0.022104736 | I21: 0.021227713 | J21: 0.022205034 | K21: 0.022470474
A22: 0010.out | B22: 0.011124676 | C22: 0.01141764 | D22: 0.011137738 | E22: 0.011229639 | F22: 0.011054701 | G22: 0.012395428 | H22: 0.011325738 | I22: 0.011184388 | J22: 0.011385917 | K22: 0.011242235
A23: 0013.out | B23: 0.015493002 | C23: 0.015330659 | D23: 0.015635751 | E23: 0.015674937 | F23: 0.015700128 | G23: 0.016275793 | H23: 0.018027507 | I23: 0.015534987 | J23: 0.015493468 | K23: 0.015830283
A24: OLDdlv
A25: OLDdlv2
A26: 0001.out | B26: 0.002280729 | C26: 0.002188361 | D26: 0.002166436 | E26: 0.002146843 | F26: 0.002182763 | G26: 0.002228014 | H26: 0.002186496 | I26: 0.002172967 | J26: 0.002180431 | K26: 0.002165036
A27: 0003.out | B27: 0.00072821 | C27: 0.00073614 | D27: 0.000739872 | E27: 0.000747803 | F27: 0.000758066 | G27: 0.000749668 | H27: 0.000735674 | I27: 0.000729609 | J27: 0.000728676 | K27: 0.000735207
A28: 0007.out | B28: 0.002654397 | C28: 0.002528441 | D28: 0.002478992 | E28: 0.00269265 | F28: 0.002663727 | G28: 0.00252331 | H28: 0.00247526 | I28: 0.002493454 | J28: 0.002674923 | K28: 0.002478526
A29: 0009.out | B29: 0.001564181 | C29: 0.00158564 | D29: 0.001470882 | E29: 0.001476013 | F29: 0.00156838 | G29: 0.001593571 | H29: 0.001587507 | I29: 0.001585174 | J29: 0.001476013 | K29: 0.001470882
A30: 0010.out | B30: 0.000937202 | C30: 0.000956329 | D30: 0.000915277 | E30: 0.000914344 | F30: 0.000907346 | G30: 0.000846701 | H30: 0.000846235 | I30: 0.000847634 | J30: 0.000845769 | K30: 0.000846701
A31: 0013.out | B31: 0.001286146 | C31: 0.001262821 | D31: 0.001260022 | E31: 0.001293143 | F31: 0.001259556 | G31: 0.00118818 | H31: 0.001171387 | I31: 0.001267486 | J31: 0.001259555 | K31: 0.001243228

Sheet hanoi_tower
A1: clingo
A2: 0001.out | B2: 0.042462153 | C2: 0.042839089 | D2: 0.043389098 | E2: 0.042477549 | F2: 0.043680663 | G2: 0.048519246 | H2: 0.0416579 | I2: 0.042414104 | J2: 0.042107144 | K2: 0.041341144
A3: 0003.out | B3: 0.06362792 | C3: 0.06197976 | D3: 0.064340738 | E3: 0.062324974 | F3: 0.091513214 | G3: 0.063450649 | H3: 0.062350631 | I3: 0.064289423 | J3: 0.063312097 | K3: 0.064789982
A4: 0009.out | B4: 0.003671388 | C4: 0.00369658 | D4: 0.003669523 | E4: 0.003686783 | F4: 0.003665791 | G4: 0.003640133 | H4: 0.003676054 | I4: 0.003684918 | J4: 0.003651796 | K4: 0.003745096
A5: 0010.out | B5: 0.003589284 | C5: 0.003695181 | D5: 0.003768889 | E5: 0.003772154 | F5: 0.003783816 | G5: 0.003748828 | H5: 0.003793146 | I5: 0.003741831 | J5: 0.003742764 | K5: 0.003749295
A6: 0011.out | B6: 0.003948492 | C6: 0.003928433 | D6: 0.003914438 | E6: 0.003910706 | F6: 0.003970418 | G6: 0.004038994 | H6: 0.004399602 | I6: 0.006543656 | J6: 0.004097307 | K6: 0.003944761
A7: 0024.out | B7: 0.089279125 | C7: 0.070820483 | D7: 0.071591615 | E7: 0.070407627 | F7: 0.071583217 | G7: 0.072044591 | H7: 0.071638732 | I7: 0.096923264 | J7: 0.071882713 | K7: 0.071050936
A8: 0029.out | B8: 0.012442136 | C8: 0.012198154 | D8: 0.011907522 | E8: 0.01222148 | F8: 0.012603546 | G8: 0.01257649 | H8: 0.01226813 | I8: 0.012618008 | J8: 0.019168661 | K8: 0.014494288
A9: 0030.out | B9: 0.013047658 | C9: 0.013039728 | D9: 0.013182478 | E9: 0.013075649 | F9: 0.012914705 | G9: 0.012989812 | H9: 0.014669228 | I9: 0.013532357 | J9: 0.013767475 | K9: 0.013777271
A10: 0031.out | B10: 0.013453518 | C10: 0.013580406 | D10: 0.013533756 | E10: 0.01329304 | F10: 0.013636387 | G10: 0.013540754 | H10: 0.013251521 | I10: 0.013326628 | J10: 0.018549144 | K10: 0.013162419
A11: 0035.out | B11: 0.014074434 | C11: 0.014282962 | D11: 0.014323081 | E11: 0.014461633 | F11: 0.014516214 | G11: 0.014735471 | H11: 0.014438775 | I11: 0.014572194 | J11: 0.01486236 | K11: 0.014788186
A12: 0037.out | B12: 0.004170082 | C12: 0.004209735 | D12: 0.004162151 | E12: 0.004251253 | F12: 0.004164484 | G12: 0.004153288 | H12: 0.004179878 | I12: 0.004206936 | J12: 0.004144425 | K12: 0.004016135
A13: 0039.out | B13: 0.004467245 | C13: 0.004338023 | D13: 0.004358083 | E13: 0.004464913 | F13: 0.00441453 | G13: 0.004769074 | H13: 0.004492437 | I13: 0.004382808 | J13: 0.004378609 | K13: 0.004326828
... A16: 0044.out | B16: 0.00837795 | C16: 0.008327568 | D16: 0.008310774 | E16: 0.008452591 | F16: 0.008687709 | G16: 0.00865832 | H16: 0.008832326 | I16: 0.008488045 | J16: 0.008501575 | K16: 0.008387281
A17: dlv
A18: dlv2
A19: 0001.out | B19: 0.047261083 | C19: 0.050021856 | D19: 0.047388439 | E19: 0.047541919 | F19: 0.046747929 | G19: 0.046488085 | H19: 0.046138208 | I19: 0.046325742 | J19: 0.046712474 | K19: 0.046559928
A20: 0003.out | B20: 0.069170457 | C20: 0.092748051 | D20: 0.069481149 | E20: 0.069208711 | F20: 0.071463792 | G20: 0.070525186 | H20: 0.068192198 | I20: 0.078737994 | J20: 0.074494671 | K20: 0.097853474
A21: 0009.out | B21: 0.004019868 | C21: 0.005040579 | D21: 0.004689768 | E21: 0.004885233 | F21: 0.003952224 | G21: 0.004219064 | H21: 0.004086577 | I21: 0.003980214 | J21: 0.003982081 | K21: 0.003977882
A22: 0010.out | B22: 0.004246123 | C22: 0.004213467 | D22: 0.004122499 | E22: 0.004150489 | F22: 0.004114101 | G22: 0.004197139 | H22: 0.004286708 | I22: 0.004135094 | J22: 0.004125298 | K22: 0.004478908
A23: 0011.out | B23: 0.004735952 | C23: 0.004224197 | D23: 0.004246122 | E23: 0.004806394 | F23: 0.004855843 | G23: 0.004289507 | H23: 0.004253586 | I23: 0.004258718 | J23: 0.004302569 | K23: 0.004227462
A24: 0024.out | B24: 0.074246491 | C24: 0.072486837 | D24: 0.071908838 | E24: 0.071734831 | F24: 0.096643828 | G24: 0.072552147 | H24: 0.071892976 | I24: 0.072161216 | J24: 0.072306766 | K24: 0.0725904
A25: 0029.out | B25: 0.012764957 | C25: 0.012707576 | D25: 0.012382423 | E25: 0.012662326 | F25: 0.012730436 | G25: 0.012779885 | H25: 0.012566693 | I25: 0.01265906 | J25: 0.012792015 | K25: 0.012777086
A26: 0030.out | B26: 0.01341433 | C26: 0.015004178 | D26: 0.01337048 | E26: 0.013993263 | F26: 0.013150756 | G26: 0.01329164 | H26: 0.013806661 | I26: 0.013453984 | J26: 0.013293506 | K26: 0.013316365
A27: 0031.out | B27: 0.013560813 | C27: 0.013693301 | D27: 0.013317764 | E27: 0.01338774 | F27: 0.01370543 | G27: 0.013614461 | H27: 0.013795464 | I27: 0.013837451 | J27: 0.013783802 | K27: 0.013639653
A28: 0035.out | B28: 0.014955661 | C28: 0.014816176 | D28: 0.015034034 | E28: 0.015286413 | F28: 0.01572446 | G28: 0.015857414 | H28: 0.015858347 | I28: 0.015831289 | J28: 0.016140582 | K28: 0.015802832
A29: 0037.out | B29: 0.004437855 | C29: 0.004570342 | D29: 0.004564278 | E29: 0.004535821 | F29: 0.004504099 | G29: 0.004478908 | H29: 0.004485439 | I29: 0.004484506 | J29: 0.004487772 | K29: 0.004449051
A30: 0039.out | B30: 0.0048829 | C30: 0.004708894 | D30: 0.004877302 | E30: 0.00478027 | F30: 0.004694899 | G30: 0.004934682 | H30: 0.00482692 | I30: 0.004803128 | J30: 0.004765341 | K30: 0.00476021
... A33: 0044.out | B33: 0.00896388 | C33: 0.009015662 | D33: 0.00863686 | E33: 0.008626597 | F33: 0.009065578 | G33: 0.008654122 | H33: 0.008660652 | I33: 0.008752553 | J33: 0.008547758 | K33: 0.008675581
A35: OLDclingo
A36: 0001.out | B36: 0.009097725 | C36: 0.012605821 | D36: 0.008665744 | E36: 0.008987163 | F36: 0.009327244 | G36: 0.008736652 | H36: 0.00873152 | I36: 0.00879683 | J36: 0.008969903 | K36: 0.008834617
A37: 0003.out | B37: 0.013606467 | C37: 0.013259857 | D37: 0.013217404 | E37: 0.013493107 | F37: 0.013093315 | G37: 0.013457187 | H37: 0.013886835 | I37: 0.013441326 | J37: 0.013581276 | K37: 0.013334496
A38: 0009.out | B38: 0.000815446 | C38: 0.000804716 | D38: 0.000797252 | E38: 0.000793987 | F38: 0.000798185 | G38: 0.00080285 | H38: 0.000797718 | I38: 0.000798651 | J38: 0.000799118 | K38: 0.000808914
A39: 0010.out | B39: 0.000841104 | C39: 0.000842036 | D39: 0.000862096 | E39: 0.001069223 | F39: 0.00100158 | G39: 0.000877024 | H39: 0.000834573 | I39: 0.000843902 | J39: 0.000823843 | K39: 0.000808448
A40: 0011.out | B40: 0.000875624 | C40: 0.000850899 | D40: 0.000856032 | E40: 0.000880756 | F40: 0.000858364 | G40: 0.000852766 | H40: 0.000827108 | I40: 0.000796319 | J40: 0.000849033 | K40: 0.000856032
A41: 0024.out | B41: 0.014657496 | C41: 0.01463697 | D41: 0.015327393 | E41: 0.015512128 | F41: 0.015400634 | G41: 0.01545195 | H41: 0.015202838 | I41: 0.014301089 | J41: 0.014715809 | K41: 0.014741001
A42: 0029.out | B42: 0.002715509 | C42: 0.002519578 | D42: 0.002537772 | E42: 0.002528908 | F42: 0.002545702 | G42: 0.002526109 | H42: 0.002527509 | I42: 0.002668859 | J42: 0.002569027 | K42: 0.00251398
A43: 0030.out | B43: 0.002846596 | C43: 0.002611479 | D43: 0.002605414 | E43: 0.00277802 | F43: 0.002792481 | G43: 0.002791083 | H43: 0.002617544 | I43: 0.002660928 | J43: 0.002589553 | K43: 0.002582089
A44: 0031.out | B44: 0.002881117 | C44: 0.002739767 | D44: 0.002828869 | E44: 0.002854526 | F44: 0.002893712 | G44: 0.002842397 | H44: 0.002827936 | I44: 0.002825137 | J44: 0.002896512 | K44: 0.002858259
A45: 0035.out | B45: 0.003214199 | C45: 0.003159152 | D45: 0.002980948 | E45: 0.002997276 | F45: 0.002960423 | G45: 0.003401734 | H45: 0.003081713 | I45: 0.003094775 | J45: 0.003082646 | K45: 0.003174547
...

Sheet keys
A1: clingo
A2: 0001.out | B2: 0.000179138 | C2: 4.0119e-05 | D2: 4.5718e-05 | E2: 4.665e-05 | F2: 8.0705e-05 | G2: 3.8254e-05 | H2: 4.1519e-05 | I2: 3.1255e-05 | J2: 3.079e-05 | K2: 3.4055e-05
A3: dlv
A4: 0001.out | B4: 0.000263108 | C4: 5.878e-05 | D4: 6.951e-05 | E4: 4.8983e-05 | F4: 4.9916e-05 | G4: 9.3301e-05 | H4: 3.6387e-05 | I4: 3.6388e-05 | J4: 8.1172e-05 | K4: 4.805e-05
A5: dlv2
A6: 0001.out | B6: 0.000114293 | C6: 4.7117e-05 | D6: 4.4318e-05 | E6: 3.4988e-05 | F6: 3.872e-05 | G6: 5.0382e-05 | H6: 3.9653e-05 | I6: 8.3971e-05 | J6: 3.0323e-05 | K6: 2.8923e-05
A8: OLDclingo
A9: 0001.out | B9: 0.000290631 | C9: 0.000108229 | D9: 6.9508e-05 | E9: 7.7439e-05 | F9: 4.1052e-05 | G9: 4.1519e-05 | H9: 5.9246e-05 | I9: 6.5777e-05 | J9: 2.4258e-05 | K9: 2.5191e-05
A10: OLDdlv
A11: 0001.out | B11: 9.9832e-05 | C11: 5.3182e-05 | D11: 3.7786e-05 | E11: 6.1112e-05 | F11: 5.3181e-05 | G11: 4.1985e-05 | H11: 4.5251e-05 | I11: 2.939e-05 | J11: 2.9857e-05 | K11: 2.6124e-05
A12: OLDdlv2
A13: 0001.out | B13: 1.5395e-05 | C13: 6.531e-06 | D13: 7.464e-06 | E13: 6.064e-06 | F13: 8.397e-06 | G13: 7.93e-06 | H13: 1.0263e-05 | I13: 1.0263e-05 | J13: 9.33e-06 | K13: 8.864e-06

Sheet labyrinth
A1: clingo
A2: 0003.out | B2: 0.65114249 | C2: 1.1006964 | D2: 0.59711616 | E2: 0.90308933 | F2: 0.64803371 | G2: 0.77783806 | H2: 1.1019354 | I2: 0.66122972 | J2: 0.66190615 | K2: 0.97410435
A3: 0011.out | B3: 1.5968666 | C3: 1.5964355 | D3: 1.114294 | E3: 1.1925086 | F3: 1.3055202 | G3: 1.7491695 | H3: 1.1227471 | I3: 1.6043418 | J3: 1.0729053 | K3: 1.2637079
A4: 0018.out | B4: 0.49514952 | C4: 0.45037491 | D4: 0.43922032 | E4: 0.4429295 | F4: 0.42782689 | G4: 0.49495826 | H4: 0.47507724 | I4: 0.46108071 | J4: 0.45749703 | K4: 0.44938778
A5: 0028.out | B5: 0.37674187 | C5: 0.42924879 | D5: 0.38219251 | E5: 0.40602201 | F5: 0.39474567 | G5: 0.34815682 | H5: 0.36621193 | I5: 0.37462067 | J5: 0.38857522 | K5: 0.43019673
A6: 0036.out | B6: 3.8713521 | C6: 4.569431 | D6: 4.0635062 | E6: 4.0131508 | F6: 4.1101207 | G6: 4.6448792 | H6: 3.9784312 | I6: 2.8702414 | J6: 3.6970521 | K6: 4.0600578
A7: 0043.out | B7: 0.42359429 | C7: 0.44966209 | D7: 0.4092992 | E7: 0.44087781 | F7: 0.41696527 | G7: 0.42555268 | H7: 0.44988041 | I7: 0.44086382 | J7: 0.4182239 | K7: 0.42350473
A8: 0051.out | B8: 1.3579707 | C8: 1.695807 | D8: 1.9026788 | E8: 1.9029289 | F8: 1.3273269 | G8: 1.3536863 | H8: 1.9578341 | I8: 1.4886623 | J8: 1.3490758 | K8: 1.2816184
A9: 0059.out | B9: 1.1963139 | C9: 1.1535415 | D9: 1.0844508 | E9: 1.1648659 | F9: 1.4957233 | G9: 1.0966583 | H9: 1.2332979 | I9: 1.1152891 | J9: 1.1100316 | K9: 1.2286454
A10: 0067.out | B10: 0.69857432 | C10: 0.65012784 | D10: 0.69780925 | E10: 0.65572776 | F10: 0.77196151 | G10: 0.71133554 | H10: 0.66626889 | I10: 0.71435476 | J10: 0.67778315 | K10: 0.66690147
A11: 0075.out | B11: 2.4828082 | C11: 1.6347593 | D11: 1.6802724 | E11: 1.6163921 | F11: 2.6225434 | G11: 1.6260376 | H11: 1.6737157 | I11: 1.5744455 | J11: 2.6619631 | K11: 1.6159877
A12: 0092.out | B12: 1.8907046 | C12: 3.1725627 | D12: 2.0441472 | E12: 2.1014073 | F12: 2.9489523 | G12: 1.9213282 | H12: 1.9087704 | I12: 2.9172538 | J12: 1.9043769 | K12: 1.9600434
A13: 0100.out | B13: 0.3736914 | C13: 0.3505192 | D13: 0.34065123 | E13: 0.33256904 | F13: 0.2977417 | G13: 0.29434228 | H13: 0.30746365 | I13: 0.32437443 | J13: 0.28708394 | K13: 0.29215205
... A19: 0175.out | B19: 2.261917 | C19: 4.2199591 | D19: 2.7241462 | E19: 2.2766912 | F19: 3.3351791 | G19: 2.1870127 | H19: 2.1727395 | I19: 3.1936921 | J19: 2.1530908 | K19: 2.1520482
A20: dlv
A21: dlv2
A22: 0003.out | B22: 0.69501116 | C22: 0.79999981 | D22: 0.80373325 | E22: 0.74214768 | F22: 0.6548442 | G22: 0.71507037 | H22: 0.67901192 | I22: 0.74140174 | J22: 0.66442434 | K22: 0.72622962
A23: 0011.out | B23: 1.1881123 | C23: 1.9698834 | D23: 1.8571816 | E23: 1.696706 | F23: 1.2987307 | G23: 1.3886923 | H23: 1.3567941 | I23: 2.1129817 | J23: 1.3351316 | K23: 1.2704223
A24: 0018.out | B24: 0.81645762 | C24: 0.72215751 | D24: 0.61858049 | E24: 0.55517789 | F24: 0.56712274 | G24: 0.554097 | H24: 0.52642304 | I24: 0.53144869 | J24: 0.52361795 | K24: 0.51860629
A25: 0028.out | B25: 0.3998427 | C25: 0.49914373 | D25: 0.53306932 | E25: 0.47729267 | F25: 0.50263505 | G25: 0.50056517 | H25: 0.41515243 | I25: 0.4342096 | J25: 0.4305648 | K25: 0.46316832
A26: 0036.out | B26: 3.7058135 | C26: 5.738487 | D26: 3.5554093 | E26: 5.1617035 | F26: 3.3449683 | G26: 5.1686936 | H26: 3.2785842 | I26: 4.7734343 | J26: 3.373411 | K26: 4.9974128
A27: 0043.out | B27: 0.51227023 | C27: 0.50619401 | D27: 0.48324433 | E27: 0.50935504 | F27: 0.52933589 | G27: 0.54784864 | H27: 0.54699074 | I27: 0.53380593 | J27: 0.49395527 | K27: 0.48194045
A28: 0051.out | B28: 1.466084 | C28: 2.2901475 | D28: 2.3528055 | E28: 1.8655642 | F28: 1.6574314 | G28: 1.6180128 | H28: 1.710758 | I28: 1.6156177 | J28: 1.9164565 | K28: 1.5576966
A29: 0059.out | B29: 1.3942376 | C29: 1.4757891 | D29: 1.4191704 | E29: 2.1772609 | F29: 1.2216264 | G29: 1.4681324 | H29: 1.3425424 | I29: 1.3830509 | J29: 1.3319402 | K29: 1.6017817
A30: 0067.out | B30: 0.90142578 | C30: 1.0907869 | D30: 0.88009067 | E30: 0.81376915 | F30: 0.80831712 | G30: 0.82818927 | H30: 0.79208883 | I30: 0.78554984 | J30: 0.86102744 | K30: 0.80837403
A31: 0075.out | B31: 3.0095815 | C31: 2.133869 | D31: 2.1303068 | E31: 1.9908318 | F31: 2.6402575 | G31: 1.9584219 | H31: 2.0238234 | I31: 1.9888058 | J31: 2.4621238 | K31: 1.9625425
A32: 0092.out | B32: 2.2934531 | C32: 3.8186255 | D32: 2.4791428 | E32: 2.366232 | F32: 3.5037868 | G32: 2.272641 | H32: 2.3237521 | I32: 3.6507105 | J32: 2.3405075 | K32: 2.355383
A33: 0100.out | B33: 0.45525361 | C33: 0.43788379 | D33: 0.41469806 | E33: 0.41754886 | F33: 0.39588301 | G33: 0.40057557 | H33: 0.38118719 | I33: 0.39847024 | J33: 0.3910211 | K33: 0.38648015
... A39: 0175.out | B39: 2.6006653 | C39: 3.9341748 | D39: 2.8854074 | E39: 2.4172685 | F39: 3.6231788 | G39: 2.2714318 | H39: 2.2850621 | I39: 3.6080566 | J39: 2.2591543 | K39: 2.2382666
A41: OLDclingo
A42: 0003.out | B42: 0.098479063 | C42: 0.043126721 | D42: 0.042357926 | E42: 0.039801494 | F42: 0.039778636 | G42: 0.038911874 | H42: 0.039348987 | I42: 0.039941911 | J42: 0.040176095 | K42: 0.04079841
A43: 0011.out | B43: 0.063639752 | C43: 0.063964437 | D43: 0.066390249 | E43: 0.06524172 | F43: 0.063607097 | G43: 0.063940646 | H43: 0.066058099 | I43: 0.068697101 | J43: 0.063536655 | K43: 0.064967417
A44: 0018.out | B44: 0.031787454 | C44: 0.030537228 | D44: 0.03048638 | E44: 0.030541427 | F44: 0.030366022 | G44: 0.030113645 | H44: 0.030275521 | I44: 0.030406608 | J44: 0.030072592 | K44: 0.030578748
A45: 0028.out | B45: 0.0273095 | C45: 0.027855774 | D45: 0.027625789 | E45: 0.027802593 | F45: 0.027796062 | G45: 0.027446186 | H45: 0.02780306 | I45: 0.02777507 | J45: 0.02711077 | K45: 0.02620389
A46: 0036.out | B46: 0.16132623 | C46: 0.15931047 | D46: 0.1707617 | E46: 0.17159114 | F46: 0.16718923 | G46: 0.15872408 | H46: 0.15976438 | I46: 0.16601971 | J46: 0.16514875 | K46: 0.1720861
A47: 0043.out | B47: 0.029381703 | C47: 0.029510457 | D47: 0.029558973 | E47: 0.028818168 | F47: 0.029860334 | G47: 0.031142748 | H47: 0.03170675 | I47: 0.052779116 | J47: 0.029622418 | K47: 0.0293901
A48: 0051.out | B48: 0.097624432 | C48: 0.088256136 | D48: 0.078828595 | E48: 0.096599993 | F48: 0.080508468 | G48: 0.080831288 | H48: 0.083003322 | I48: 0.086369134 | J48: 0.0838225 | K48: 0.081996611
A49: 0059.out | B49: 0.068113041 | C49: 0.06705968 | D49: 0.066873545 | E49: 0.067261674 | F49: 0.069541003 | G49: 0.069458899 | H49: 0.067581229 | I49: 0.070282742 | J49: 0.067902182 | K49: 0.070063486
A50: 0067.out | B50: 0.045525009 | C50: 0.046037228 | D50: 0.044118504 | E50: 0.044892899 | F50: 0.047335503 | G50: 0.04719322 | H50: 0.045717207 | I50: 0.043499457 | J50: 0.044076052 | K50: 0.043587625
A51: 0075.out | B51: 0.095553628 | C51: 0.097792838 | D51: 0.094351453 | E51: 0.094256752 | F51: 0.094141526 | G51: 0.098244412 | H51: 0.10568792 | I51: 0.10831573 | J51: 0.092938884 | K51: 0.09312082
...

Sheet ladder
A1: clingo
A2: 0001.out | B2: 0.003269728 | C2: 0.003348102 | D2: 0.003187157 | E2: 0.003178294 | F2: 0.003194155 | G2: 0.003295386 | H2: 0.003066333 | I2: 0.003035543 | J2: 0.00310272 | K2: 0.003133043
A3: 0002.out | B3: 0.000394663 | C3: 0.000355476 | D3: 0.000357809 | E3: 0.000358742 | F3: 0.000405859 | G3: 0.000348945 | H3: 0.00033495 | I3: 0.00033495 | J3: 0.00033355 | K3: 0.000334484
A4: 0003.out | B4: 0.003114849 | C4: 0.003301917 | D4: 0.003343436 | E4: 0.003284656 | F4: 0.003212815 | G4: 0.003243605 | H4: 0.003274393 | I4: 0.003148904 | J4: 0.003155435 | K4: 0.003348101
A5: 0004.out | B5: 0.003627071 | C5: 0.003701245 | D5: 0.003610277 | E5: 0.003725503 | F5: 0.00378988 | G5: 0.00538206 | H5: 0.003676987 | I5: 0.003667657 | J5: 0.003595349 | K5: 0.003623805
A6: 0005.out | B6: 0.003963887 | C6: 0.003958289 | D6: 0.003950358 | E6: 0.003941028 | F6: 0.00404086 | G6: 0.004518094 | H6: 0.004859575 | I6: 0.004776537 | J6: 0.004786801 | K6: 0.004768141
A7: 0006.out | B7: 0.005139011 | C7: 0.00490436 | D7: 0.004811525 | E7: 0.004770939 | F7: 0.068238848 | G7: 0.0056517 | H7: 0.005615779 | I7: 0.005415182 | J7: 0.005369931 | K7: 0.005415181
A8: 0007.out | B8: 0.005559332 | C8: 0.005368531 | D8: 0.005316749 | E8: 0.005313484 | F8: 0.005078366 | G8: 0.005173532 | H8: 0.005381593 | I8: 0.005097026 | J8: 0.005262169 | K8: 0.005167934
A9: 0008.out | B9: 0.00572774 | C9: 0.005705348 | D9: 0.005765993 | E9: 0.005699749 | F9: 0.005522478 | G9: 0.005465098 | H9: 0.005328879 | I9: 0.00528596 | J9: 0.005214585 | K9: 0.005155339
A10: 0009.out | B10: 0.005629308 | C10: 0.006102343 | D10: 0.006109807 | E10: 0.005845765 | F10: 0.005970322 | G10: 0.005626508 | H10: 0.005619044 | I10: 0.005472561 | J10: 0.005390923 | K10: 0.005409584
A11: 0010.out | B11: 0.005554667 | C11: 0.005664762 | D11: 0.00599458 | E11: 0.006052894 | F11: 0.00583457 | G11: 0.005799582 | H11: 0.005712345 | I11: 0.005653565 | J11: 0.005542537 | K11: 0.00549822
A12: 0011.out | B12: 0.005977786 | C12: 0.005897547 | D12: 0.005651699 | E12: 0.005613912 | F12: 0.005761794 | G12: 0.006079018 | H12: 0.005941399 | I12: 0.006065955 | J12: 0.005835036 | K12: 0.005827572
A13: 0012.out | B13: 0.006064556 | C13: 0.006195177 | D13: 0.006944383 | E13: 0.007258341 | F13: 0.007670264 | G13: 0.007653936 | H13: 0.007644606 | I13: 0.020929715 | J13: 0.007617548 | K13: 0.00755457
... A21: 0020.out | B21: 0.002675403 | C21: 0.00263295 | D21: 0.002457078 | E21: 0.002465009 | F21: 0.002528453 | G21: 0.002590965 | H21: 0.002491133 | I21: 0.002454746 | J21: 0.002446815 | K21: 0.002582101
A22: dlv
A23: 0001.out | B23: 0.003499249 | C23: 0.003232408 | D23: 0.003402216 | E23: 0.003247803 | F23: 0.003451199 | G23: 0.003587885 | H23: 0.003448866 | I23: 0.003393352 | J23: 0.003685851 | K23: 0.003968552
A24: 0002.out | B24: 0.000645642 | C24: 0.000539279 | D24: 0.000515488 | E24: 0.000552341 | F24: 0.00050569 | G24: 0.000498694 | H24: 0.000536946 | I24: 0.000531815 | J24: 0.000498227 | K24: 0.000501492
A25: 0003.out | B25: 0.004763942 | C25: 0.004742482 | D25: 0.004772806 | E25: 0.004751347 | F25: 0.004672973 | G25: 0.005004658 | H25: 0.004923486 | I25: 0.004918821 | J25: 0.004916488 | K25: 0.004756945
A26: 0004.out | B26: 0.005601317 | C26: 0.00538206 | D26: 0.005607381 | E26: 0.005242109 | F26: 0.005244441 | G26: 0.005153473 | H26: 0.005253305 | I26: 0.005177264 | J26: 0.005179597 | K26: 0.005273364
A27: 0005.out | B27: 0.005294357 | C27: 0.005187528 | D27: 0.004978534 | E27: 0.005053641 | F27: 0.005026117 | G27: 0.004940747 | H27: 0.004773739 | I27: 0.008397078 | J27: 0.005292025 | K27: 0.004992062
A28: 0006.out | B28: 0.005251905 | C28: 0.005021452 | D28: 0.005272431 | E28: 0.005160004 | F28: 0.005526676 | G28: 0.005436174 | H28: 0.00556493 | I28: 0.005617645 | J28: 0.005477694 | K28: 0.005529009
A29: 0007.out | B29: 0.00587189 | C29: 0.00566103 | D29: 0.005649367 | E29: 0.005596652 | F29: 0.00543944 | G29: 0.005417514 | H29: 0.005306019 | I29: 0.005292025 | J29: 0.005403985 | K29: 0.005048976
A30: 0008.out | B30: 0.005346139 | C30: 0.005446904 | D30: 0.005249573 | E30: 0.005300889 | F30: 0.005328879 | G30: 0.005435708 | H30: 0.005407718 | I30: 0.005405385 | J30: 0.005614379 | K30: 0.005688553
A31: 0009.out | B31: 0.005783254 | C31: 0.005729139 | D31: 0.005804246 | E31: 0.005798648 | F31: 0.005774857 | G31: 0.005706747 | H31: 0.005770658 | I31: 0.005760862 | J31: 0.005821973 | K31: 0.005759929
A32: 0010.out | B32: 0.006006243 | C32: 0.006273084 | D32: 0.006145728 | E32: 0.006391576 | F32: 0.006599636 | G32: 0.006754516 | H32: 0.006700868 | I32: 0.006948582 | J32: 0.007473866 | K32: 0.007258807
A33: 0011.out | B33: 0.007362371 | C33: 0.007359105 | D33: 0.007263472 | E33: 0.007037217 | F33: 0.006793235 | G33: 0.006764312 | H33: 0.006799766 | I33: 0.00677131 | J33: 0.00687394 | K33: 0.010361994
A34: 0012.out | B34: 0.007120255 | C34: 0.00686461 | D34: 0.007145913 | E34: 0.007345577 | F34: 0.007121188 | G34: 0.007037217 | H34: 0.0069901 | I34: 0.006927589 | J34: 0.007092265 | K34: 0.007620347
... A42: 0020.out | B42: 0.003099921 | C42: 0.002947374 | D42: 0.002881597 | E42: 0.002908654 | F42: 0.002889994 | G42: 0.002931979 | H42: 0.002890461 | I42: 0.002917518 | J42: 0.00290259 | K42: 0.002896058
A43: dlv2
A44: 0001.out | B44: 0.002928714 | C44: 0.003103186 | D44: 0.0029665 | E44: 0.002883463 | F44: 0.003073796 | G44: 0.003013151 | H44: 0.002882064 | I44: 0.002883929 | J44: 0.003095256 | K44: 0.00327346
A45: 0002.out | B45: 0.000405859 | C45: 0.000371337 | D45: 0.000362473 | E45: 0.000367139 | F45: 0.000359675 | G45: 0.000356876 | H45: 0.000360608 | I45: 0.000359208 | J45: 0.000362941 | K45: 0.000354543
A46: 0003.out | B46: 0.003270662 | C46: 0.003248269 | D46: 0.003230076 | E46: 0.003225411 | F46: 0.003215148 | G46: 0.003553829 | H46: 0.003415278 | I46: 0.003310781 | J46: 0.003449332 | K46: 0.007583493
A47: 0004.out | B47: 0.00397415 | C47: 0.0039275 | D47: 0.003927033 | E47: 0.003978348 | F47: 0.004349686 | G47: 0.004259651 | H47: 0.004230727 | I47: 0.004264316 | J47: 0.004253586 | K47: 0.004221397
A48: 0005.out | B48: 0.004442521 | C48: 0.004279711 | D48: 0.004297904 | E48: 0.004400535 | F48: 0.004438321 | G48: 0.00503778 | H48: 0.004998127 | I48: 0.004781203 | J48: 0.004945878 | K48: 0.004728487
A49: 0006.out | B49: 0.004841382 | C49: 0.004703297 | D49: 0.004620725 | E49: 0.004682303 | F49: 0.004893163 | G49: 0.005060638 | H49: 0.004973402 | I49: 0.005004192 | J49: 0.005006524 | K49: 0.00521132
A50: 0007.out | B50: 0.005444106 | C50: 0.005434775 | D50: 0.005306487 | E50: 0.00522718 | F50: 0.005220183 | G50: 0.005223448 | H50: 0.005241642 | I50: 0.005294824 | J50: 0.005253304 | K50: 0.005148808
A51: 0008.out | B51: 0.005313018 | C51: 0.005178198 | D51: 0.005319549 | E51: 0.005142277 | F51: 0.005174466 | G51: 0.005417981 | H51: 0.005301355 | I51: 0.005241643 | J51: 0.005236044 | K51: 0.005200123
A52: 0009.out | B52: 0.005422179 | C52: 0.005524344 | D52: 0.005205254 | E52: 0.005521078 | F52: 0.005591987 | G52: 0.005570995 | H52: 0.005347072 | I52: 0.005174 | J52: 0.005563063 | K52: 0.005512681
A53: 0010.out | B53: 0.005777189 | C53: 0.005866758 | D53: 0.005534141 | E53: 0.005765993 | F53: 0.005865358 | G53: 0.006160189 | H53: 0.0064163 | I53: 0.00674192 | J53: 0.010074627 | K53: 0.006536192
A54: 0011.out | B54: 0.006596837 | C54: 0.006502137 | D54: 0.006505402 | E54: 0.006580043 | F54: 0.006836154 | G54: 0.006712064 | H54: 0.006569313 | I54: 0.006404638 | J54: 0.006642088 | K54: 0.006395307
...

Sheet maximal_clique_problem
A1: clingo
A2: 0001.out | B2: 5.3641402 | C2: 5.6938967 | D2: 6.437971 | E2: 5.192022 | F2: 5.5823569 | G2: 6.0577738 | H2: 5.5602856 | I2: 5.7252052 | J2: 6.098828 | K2: 5.4820958
A3: 0002.out | B3: 1.5457932 | C3: 1.8224181 | D3: 1.6176946 | E3: 3.0486293 | F3: 1.5197656 | G3: 1.6707492 | H3: 2.1083512 | I3: 1.4799396 | J3: 3.0960766 | K3: 1.5001579
A4: 0003.out | B4: 0.36761098 | C4: 0.43163683 | D4: 0.41511091 | E4: 0.43679403 | F4: 0.46555962 | G4: 0.43369971 | H4: 0.39141483 | I4: 0.34421812 | J4: 0.33531675 | K4: 0.32069324
A5: 0006.out | B5: 2.1696336 | C5: 3.054253 | D5: 2.1827671 | E5: 3.6842974 | F5: 1.9684998 | G5: 3.5443191 | H5: 2.0872186 | I5: 3.6075565 | J5: 2.0306675 | K5: 3.5505352
A6: 0008.out | B6: 5.4908358 | C6: 6.6582497 | D6: 5.6341272 | E6: 5.3350555 | F6: 5.3824934 | G6: 5.4484968 | H6: 6.0477061 | I6: 5.4151604 | J6: 5.9557628 | K6: 5.4912001
A7: 0009.out | B7: 5.8741255 | C7: 6.429497 | D7: 6.1950823 | E7: 5.7581698 | F7: 5.7571547 | G7: 5.7019947 | H7: 5.5690032 | I7: 5.7588495 | J7: 6.6671315 | K7: 6.5360214
A8: 0010.out | B8: 6.4773123 | C8: 6.266701 | D8: 7.2396083 | E8: 6.1370692 | F8: 6.6602692 | G8: 6.1393742 | H8: 5.9286496 | I8: 6.4766186 | J8: 5.9339528 | K8: 6.6211131
A9: 0011.out | B9: 6.3909021 | C9: 6.362263 | D9: 5.969889 | E9: 5.3207329 | F9: 5.0705023 | G9: 5.9465288 | H9: 5.663998 | I9: 4.4767142 | J9: 8.3101726 | K9: 6.4308732
A10: 0012.out | B10: 3.5012201 | C10: 4.9925835 | D10: 4.8689935 | E10: 4.9416067 | F10: 4.6416179 | G10: 4.8056473 | H10: 4.6283304 | I10: 4.6326703 | J10: 4.7103475 | K10: 4.8136231
A11: 0014.out | B11: 27.971296 | C11: 29.031297 | D11: 30.159709 | E11: 29.390782 | F11: 27.767946 | G11: 22.832646 | H11: 27.081147 | I11: 27.954432 | J11: 26.757344 | K11: 21.97225
A12: 0017.out | B12: 2.3965856 | C12: 4.7922269 | D12: 4.7570189 | E12: 4.9022156 | F12: 4.4234567 | G12: 4.4801281 | H12: 4.80646 | I12: 4.5514449 | J12: 4.4993425 | K12: 4.5716996
A13: 0018.out | B13: 0.92807483 | C13: 1.1006217 | D13: 2.1310616 | E13: 1.0207772 | F13: 1.1861697 | G13: 0.99169669 | H13: 1.0268049 | I13: 1.3337941 | J13: 0.96256116 | K13: 1.0182543
... A17: 0026.out | B17: 26.720967 | C17: 26.69175 | D17: 25.334472 | E17: 22.860776 | F17: 23.118035 | G17: 19.019105 | H17: 22.938746 | I17: 23.101505 | J17: 23.069205 | K17: 23.46757
A18: dlv
A19: dlv2
A20: 0001.out | B20: 2.2064482 | C20: 2.4611204 | D20: 4.1963251 | E20: 2.3140605 | F20: 4.2399483 | G20: 2.1921144 | H20: 3.9725868 | I20: 2.2261016 | J20: 3.9835473 | K20: 2.1955306
A21: 0002.out | B21: 3.1722884 | C21: 1.863193 | D21: 3.5319096 | E21: 1.7972619 | F21: 3.3303046 | G21: 1.7495964 | H21: 3.4061158 | I21: 1.7965108 | J21: 3.3380542 | K21: 1.7066826
A22: 0003.out | B22: 3.5804027 | C22: 1.8660951 | D22: 3.5810773 | E22: 1.7899681 | F22: 3.255392 | G22: 1.6616748 | H22: 3.407784 | I22: 1.6570489 | J22: 3.4139036 | K22: 1.6362372
A23: 0006.out | B23: 4.4079566 | C23: 2.5135932 | D23: 3.9353761 | E23: 4.6255169 | F23: 2.3436084 | G23: 4.8538815 | H23: 4.7053097 | I23: 2.2857889 | J23: 4.1636506 | K23: 4.5492356
A24: 0008.out | B24: 5.8166848 | C24: 6.1623696 | D24: 6.9371969 | E24: 6.2893479 | F24: 5.7875469 | G24: 5.7723646 | H24: 5.7347555 | I24: 5.4889338 | J24: 5.5559462 | K24: 6.3639447
A25: 0009.out | B25: 4.7632519 | C25: 5.2404657 | D25: 5.6504381 | E25: 5.302779 | F25: 4.949911 | G25: 5.1308806 | H25: 5.3278942 | I25: 4.9056113 | J25: 4.9973535 | K25: 5.0671538
A26: 0010.out | B26: 5.3349142 | C26: 5.6185152 | D26: 5.7521542 | E26: 5.4706137 | F26: 5.2769267 | G26: 5.4134156 | H26: 5.5892938 | I26: 5.3956418 | J26: 5.3171823 | K26: 5.7605648
A27: 0011.out | B27: 5.2528192 | C27: 5.8259048 | D27: 5.6434218 | E27: 5.5534028 | F27: 5.4157999 | G27: 5.2887666 | H27: 5.6975527 | I27: 5.3581279 | J27: 5.2340853 | K27: 5.4087035
A28: 0012.out | B28: 4.7993626 | C28: 4.8961949 | D28: 5.0244672 | E28: 4.7618155 | F28: 4.6381536 | G28: 2.3690161 | H28: 2.4424747 | I28: 4.9069954 | J28: 4.8765536 | K28: 4.7117465
A29: 0014.out | B29: 10.07435 | C29: 7.34993 | D29: 6.2374484 | E29: 9.6311341 | F29: 6.0533028 | G29: 8.7316798 | H29: 9.4763321 | I29: 9.6792321 | J29: 9.3570703 | K29: 9.4536082
A30: 0017.out | B30: 5.8016214 | C30: 9.2461724 | D30: 10.703445 | E30: 9.7053927 | F30: 9.5586053 | G30: 5.8178035 | H30: 6.9971968 | I30: 10.077644 | J30: 9.8420617 | K30: 9.4713704
A31: 0018.out | B31: 5.2821362 | C31: 5.9477912 | D31: 7.2237886 | E31: 6.7082193 | F31: 6.7452299 | G31: 6.7625442 | H31: 6.6146493 | I31: 6.6654045 | J31: 6.5282 | K31: 6.7036088
... A35: 0026.out | B35: 12.555472 | C35: 14.051326 | D35: 15.429077 | E35: 14.773033 | F35: 16.444672 | G35: 17.058633 | H35: 14.59642 | I35: 14.78522 | J35: 15.720868 | K35: 16.792221
A37: OLDclingo
A38: 0001.out | B38: 0.3560708 | C38: 0.34287252 | D38: 0.3481286 | E38: 0.34781838 | F38: 0.37004674 | G38: 0.35970252 | H38: 0.35120659 | I38: 0.34397347 | J38: 0.37179052 | K38: 0.34129901
A39: 0002.out | B39: 0.17445267 | C39: 0.18061982 | D39: 0.17365868 | E39: 0.17178101 | F39: 0.17093337 | G39: 0.17684629 | H39: 0.18304423 | I39: 0.18538654 | J39: 0.17468218 | K39: 0.17148758
A40: 0003.out | B40: 0.057691383 | C40: 0.057092395 | D40: 0.057668058 | E40: 0.057059273 | F40: 0.059561591 | G40: 0.06164079 | H40: 0.061999531 | I40: 0.064913769 | J40: 0.061986002 | K40: 0.058762006
A41: 0006.out | B41: 0.22966319 | C41: 0.22839384 | D41: 0.23067643 | E41: 0.24793841 | F41: 0.23555558 | G41: 0.24733802 | H41: 0.23049963 | I41: 0.2444597 | J41: 0.24120119 | K41: 0.23337841
A42: 0008.out | B42: 0.35698655 | C42: 0.36228368 | D42: 0.33589179 | E42: 0.34891886 | F42: 0.35837672 | G42: 0.33482536 | H42: 0.36302495 | I42: 0.34376634 | J42: 0.3403814 | K42: 0.37004814
A43: 0009.out | B43: 0.3943515 | C43: 0.39914434 | D43: 0.36820452 | E43: 0.36666926 | F43: 0.3889606 | G43: 0.37265495 | H43: 0.38110657 | I43: 0.37899145 | J43: 0.36679569 | K43: 0.38111823
A44: 0010.out | B44: 0.39346888 | C44: 0.41035345 | D44: 0.39825146 | E44: 0.38409638 | F44: 0.40945217 | G44: 0.38577812 | H44: 0.40567304 | I44: 0.39166025 | J44: 0.3873605 | K44: 0.4080396
A45: 0011.out | B45: 0.50311553 | C45: 0.49581384 | D45: 0.47388265 | E45: 0.49343468 | F45: 0.49740135 | G45: 0.50432891 | H45: 0.47725966 | I45: 0.49313659 | J45: 0.48885363 | K45: 0.49544297
A46: 0012.out | B46: 0.27852975 | C46: 0.30139116 | D46: 0.28626716 | E46: 0.28805386 | F46: 0.29950649 | G46: 0.29174716 | H46: 0.27776189 | I46: 0.27881432 | J46: 0.30730454 | K46: 0.28201779
A47: 0014.out | B47: 0.71674411 | C47: 0.68211193 | D47: 0.71046593 | E47: 0.70129123 | F47: 0.68308132 | G47: 0.7037511 | H47: 0.6860702 | I47: 0.6599027 | J47: 0.70885789 | K47: 0.69313584
...

Sheet network
A1: clingo
A2: 0001.out | B2: 0.00033495 | C2: 0.000285967 | D2: 0.000285967 | E2: 0.000272905 | F2: 0.000276637 | G2: 0.000270106 | H2: 0.000259376 | I2: 0.000271039 | J2: 0.000271039 | K2: 0.000257511
A3: dlv
A4: 0001.out | B4: 0.00042172 | C4: 0.000312558 | D4: 0.000262175 | E4: 0.000274304 | F4: 0.000250046 | G4: 0.000323754 | H4: 0.000338682 | I4: 0.0002855 | J4: 0.000275238 | K4: 0.000247714
A5: dlv2
A6: 0001.out | B6: 0.000287367 | C6: 0.000334017 | D6: 0.000274305 | E6: 0.000251913 | F6: 0.000236517 | G6: 0.000257044 | H6: 0.000234652 | I6: 0.000232319 | J6: 0.000233252 | K6: 0.000233718
A8: OLDclingo
A9: 0001.out | B9: 4.0119e-05 | C9: 2.3791e-05 | D9: 2.3326e-05 | E9: 1.9127e-05 | F9: 2.006e-05 | G9: 2.0993e-05 | H9: 2.006e-05 | I9: 1.9593e-05 | J9: 2.006e-05 | K9: 2.006e-05
A10: OLDdlv
A11: 0001.out | B11: 5.0382e-05 | C11: 2.1925e-05 | D11: 1.866e-05 | E11: 1.866e-05 | F11: 1.8193e-05 | G11: 1.866e-05 | H11: 1.8194e-05 | I11: 1.7727e-05 | J11: 1.8194e-05 | K11: 1.866e-05
A12: OLDdlv2
A13: 0001.out | B13: 8.397e-06 | C13: 4.199e-06 | D13: 3.732e-06 | E13: 4.199e-06 | F13: 3.732e-06 | G13: 3.732e-06 | H13: 4.665e-06 | I13: 4.199e-06 | J13: 4.665e-06 | K13: 3.732e-06

Sheet stable_marriage
A1: clingo
A2: 0001.out | B2: 4.8549899 | C2: 6.7413439 | D2: 6.1263965 | E2: 6.6509503 | F2: 5.851061 | G2: 5.8274592 | H2: 6.4304137 | I2: 6.340069 | J2: 5.767394 | K2: 5.8690882
A3: 0002.out | B3: 0.8544488 | C3: 0.81496947 | D3: 0.63522817 | E3: 0.59834774 | F3: 0.60693701 | G3: 0.6133911 | H3: 0.63125588 | I3: 0.60465487 | J3: 0.618093 | K3: 0.63543996
A4: 0003.out | B4: 1.9365871 | C4: 2.2192761 | D4: 1.942724 | E4: 1.8725902 | F4: 1.8131655 | G4: 1.8662159 | H4: 1.7896551 | I4: 1.7957182 | J4: 1.8083778 | K4: 1.8147008
A5: 0006.out | B5: 2.8326085 | C5: 4.4536465 | D5: 3.543624 | E5: 2.7518295 | F5: 3.3483262 | G5: 3.3211294 | H5: 3.5534159 | I5: 2.9573373 | J5: 2.881089 | K5: 2.83687
A6: 0008.out | B6: 4.1228455 | C6: 4.3992316 | D6: 4.7151072 | E6: 4.3743366 | F6: 4.9398881 | G6: 4.5640681 | H6: 4.7190711 | I6: 3.6083319 | J6: 4.2868843 | K6: 4.3648539
A7: 0009.out | B7: 0.67945324 | C7: 0.69642933 | D7: 0.60800018 | E7: 0.58805059 | F7: 0.58655031 | G7: 0.61372885 | H7: 0.61082019 | I7: 0.56745116 | J7: 0.58623029 | K7: 0.58060984
A8: 0010.out | B8: 0.57987416 | C8: 0.5955697 | D8: 0.60499356 | E8: 0.62489043 | F8: 0.55258926 | G8: 0.53013314 | H8: 0.5358105 | I8: 0.56050724 | J8: 0.56330067 | K8: 0.5727707
A9: 0011.out | B9: 1.9470718 | C9: 2.8033218 | D9: 3.5952152 | E9: 2.1705512 | F9: 2.2429111 | G9: 2.4460826 | H9: 2.2588441 | I9: 2.332723 | J9: 2.2519636 | K9: 2.0870744
A10: 0012.out | B10: 0.56889125 | C10: 0.60872792 | D10: 0.60084493 | E10: 0.5469189 | F10: 0.5770896 | G10: 0.59162308 | H10: 0.57015548 | I10: 0.53074287 | J10: 0.52476695 | K10: 0.52289067
A11: 0014.out | B11: 8.5414211 | C11: 9.7956357 | D11: 7.0531255 | E11: 7.0811689 | F11: 7.0298726 | G11: 6.8257826 | H11: 8.8177316 | I11: 6.8060536 | J11: 6.6760072 | K11: 7.0116211
A12: 0017.out | B12: 6.2932119 | C12: 8.4553161 | D12: 6.0072336 | E12: 6.0033532 | F12: 6.9868744 | G12: 5.9173261 | H12: 5.9865455 | I12: 6.7665351 | J12: 6.1946382 | K12: 6.0642703
A13: 0018.out | B13: 4.4677825 | C13: 4.0801188 | D13: 3.7444331 | E13: 3.9262494 | F13: 3.9236514 | G13: 4.6741855 | H13: 3.7740351 | I13: 3.6644173 | J13: 3.7087143 | K13: 3.852315
... A18: 0026.out | B18: 3.4129487 | C18: 3.5518242 | D18: 3.3610426 | E18: 3.1812686 | F18: 3.1075628 | G18: 3.1062137 | H18: 3.3397887 | I18: 3.1539609 | J18: 3.276826 | K18: 3.2327264
A19: dlv
A20: dlv2
A21: 0001.out | B21: 4.2306267 | C21: 5.318301 | D21: 4.6649277 | E21: 4.4138985 | F21: 4.4238761 | G21: 4.9737839 | H21: 4.3124259 | I21: 4.362499 | J21: 4.325689 | K21: 5.1727783
A22: 0002.out | B22: 0.63357674 | C22: 0.60620133 | D22: 0.52898974 | E22: 0.51080447 | F22: 0.51458876 | G22: 0.51520361 | H22: 0.49467509 | I22: 0.5379233 | J22: 0.48766166 | K22: 0.48830544
A23: 0003.out | B23: 1.6521828 | C23: 1.8879681 | D23: 1.943573 | E23: 1.6845171 | F23: 1.7781418 | G23: 1.7235127 | H23: 1.7330625 | I23: 1.7856212 | J23: 2.2505165 | K23: 1.7632337
A24: 0006.out | B24: 2.5224372 | C24: 2.6882496 | D24: 2.5738129 | E24: 2.6050761 | F24: 2.5650981 | G24: 2.5634056 | H24: 2.6180636 | I24: 2.5254798 | J24: 2.607598 | K24: 2.5809607
A25: 0008.out | B25: 3.4232132 | C25: 3.4357519 | D25: 3.8717813 | E25: 3.5642603 | F25: 3.4466835 | G25: 3.4582266 | H25: 3.3770418 | I25: 4.1934873 | J25: 3.5840191 | K25: 3.5655819
A26: 0009.out | B26: 0.60519369 | C26: 0.60049272 | D26: 0.53389177 | E26: 0.55429713 | F26: 0.54913247 | G26: 0.56802682 | H26: 0.61052023 | I26: 0.52378449 | J26: 0.5341782 | K26: 0.55446088
A27: 0010.out | B27: 0.52976974 | C27: 0.5852287 | D27: 0.52251793 | E27: 0.54500157 | F27: 0.557746 | G27: 0.54215823 | H27: 0.54652237 | I27: 0.52303435 | J27: 0.52968763 | K27: 0.54294849
A28: 0011.out | B28: 1.9956629 | C28: 2.1451057 | D28: 2.0651329 | E28: 2.1306562 | F28: 2.0869774 | G28: 2.016246 | H28: 2.0749962 | I28: 1.9869523 | J28: 2.0350382 | K28: 2.0718258
A29: 0012.out | B29: 0.5819879 | C29: 0.55877791 | D29: 0.55391413 | E29: 0.5373369 | F29: 0.53290511 | G29: 0.54307911 | H29: 0.50937837 | I29: 0.49546301 | J29: 0.52313558 | K29: 0.48499186
A30: 0014.out | B30: 8.0849014 | C30: 6.709282 | D30: 8.5736967 | E30: 6.4241494 | F30: 8.4850138 | G30: 6.1958534 | H30: 8.5604452 | I30: 6.232578 | J30: 7.8683642 | K30: 6.4674784
A31: 0017.out | B31: 7.2227628 | C31: 6.4313681 | D31: 5.7898543 | E31: 6.1740383 | F31: 5.8438699 | G31: 5.7250232 | H31: 6.0999672 | I31: 5.7487865 | J31: 5.9879255 | K31: 5.9458566
A32: 0018.out | B32: 3.5147152 | C32: 3.9637293 | D32: 3.6164467 | E32: 4.1656711 | F32: 3.6282675 | G32: 3.5686114 | H32: 3.5078394 | I32: 3.5249377 | J32: 3.8916385 | K32: 3.7650428
... A37: 0026.out | B37: 3.0250494 | C37: 4.026991 | D37: 2.9879446 | E37: 3.0967171 | F37: 3.0046515 | G37: 2.980697 | H37: 2.9699221 | I37: 3.3161677 | J37: 3.0243268 | K37: 2.9850812
A39: OLDclingo
A40: 0001.out | B40: 0.20730934 | C40: 0.19548398 | D40: 0.20351295 | E40: 0.19454071 | F40: 0.2017519 | G40: 0.20593316 | H40: 0.19537109 | I40: 0.19702484 | J40: 0.19404902 | K40: 0.20067055
A41: 0002.out | B41: 0.027088378 | C41: 0.027257252 | D41: 0.028324142 | E41: 0.027137828 | F41: 0.02670398 | G41: 0.026145577 | H41: 0.026957758 | I41: 0.025853548 | J41: 0.026162838 | K41: 0.025906262
A42: 0003.out | B42: 0.078942421 | C42: 0.08128846 | D42: 0.084632814 | E42: 0.082921684 | F42: 0.079883355 | G42: 0.077827481 | H42: 0.082693098 | I42: 0.077736047 | J42: 0.077385237 | K42: 0.077742577
A43: 0006.out | B43: 0.11714521 | C43: 0.12543962 | D43: 0.12458499 | E43: 0.11713915 | F43: 0.11815426 | G43: 0.11782024 | H43: 0.11579469 | I43: 0.11988311 | J43: 0.11947586 | K43: 0.12441658
A44: 0008.out | B44: 0.15795855 | C44: 0.16106265 | D44: 0.15605149 | E44: 0.1607515 | F44: 0.16618671 | G44: 0.16326221 | H44: 0.16061108 | I44: 0.15743513 | J44: 0.15669293 | K44: 0.15637757
A45: 0009.out | B45: 0.026947494 | C45: 0.027219465 | D45: 0.026600417 | E45: 0.026797281 | F45: 0.026679256 | G45: 0.026617677 | H45: 0.026910641 | I45: 0.026113389 | J45: 0.026662929 | K45: 0.026280396
A46: 0010.out | B46: 0.026137181 | C46: 0.026230015 | D46: 0.027019336 | E46: 0.025955245 | F46: 0.026770224 | G46: 0.026996478 | H46: 0.026404487 | I46: 0.026295325 | J46: 0.02624261 | K46: 0.026356903
A47: 0011.out | B47: 0.097766715 | C47: 0.098868126 | D47: 0.095629668 | E47: 0.091468003 | F47: 0.091940103 | G47: 0.096177341 | H47: 0.10022331 | I47: 0.092709364 | J47: 0.095990274 | K47: 0.094625289
A48: 0012.out | B48: 0.028515409 | C48: 0.029530983 | D48: 0.028333939 | E48: 0.02843657 | F48: 0.026362967 | G48: 0.026701649 | H48: 0.026221617 | I48: 0.02646 | J48: 0.026660596 | K48: 0.028361929
A49: 0014.out | B49: 0.30612569 | C49: 0.32266179 | D49: 0.30539561 | E49: 0.30190897 | F49: 0.31660332 | G49: 0.31320719 | H49: 0.30316666 | I49: 0.31328369 | J49: 0.31729328 | K49: 0.29882819
...

Sheet visit_all
A1: clingo
A2: 0002.out | B2: 0.001207313 | C2: 0.001191919 | D2: 0.001239035 | E2: 0.001153199 | F2: 0.001171859 | G2: 0.001191452 | H2: 0.001184455 | I2: 0.001158331 | J2: 0.001192385 | K2: 0.001183988
A3: 0007.out | B3: 0.000205262 | C3: 1.9127e-05 | D3: 1.4928e-05 | E3: 2.2859e-05 | F3: 1.3062e-05 | G3: 1.2595e-05 | H3: 1.2129e-05 | I3: 1.213e-05 | J3: 1.1663e-05 | K3: 1.6794e-05
A4: 0024.out | B4: 0.004986931 | C4: 0.004652447 | D4: 0.004527891 | E4: 0.004646383 | F4: 0.005251905 | G4: 0.094150829 | H4: 0.005843433 | I4: 0.005841567 | J4: 0.005817775 | K4: 0.00582244
A5: 0027.out | B5: 0.024616965 | C5: 0.024312337 | D5: 0.022982334 | E5: 0.024054827 | F5: 0.024426165 | G5: 0.023288827 | H5: 0.023032717 | I5: 0.024073954 | J5: 0.024977573 | K5: 0.025065742
A6: 0041.out | B6: 0.002604027 | C6: 0.00257417 | D6: 0.002561108 | E6: 0.002566706 | F6: 0.002450547 | G6: 0.002439817 | H6: 0.002436552 | I6: 0.0023941 | J6: 0.002504661 | K6: 0.002353048
A7: 0048.out | B7: 0.006024903 | C7: 0.006258622 | D7: 0.006634157 | E7: 0.006699468 | F7: 0.006848749 | G7: 0.00694065 | H7: 0.006912661 | I7: 0.007044215 | J7: 0.006638823 | K7: 0.00668594
A8: 0062.out | B8: 0.013373745 | C8: 0.013299571 | D8: 0.01434594 | E8: 0.013964806 | F8: 0.013384008 | G8: 0.013464714 | H8: 0.013090577 | I8: 0.012854059 | J8: 0.013743216 | K8: 0.014571728
A9: 0066.out | B9: 0.02582801 | C9: 0.024977106 | D9: 0.025605488 | E9: 0.025055945 | F9: 0.02440144 | G9: 0.025441744 | H9: 0.10249799 | I9: 0.028147003 | J9: 0.028321476 | K9: 0.027726682
A10: 0081.out | B10: 0.035321839 | C10: 0.038008438 | D10: 0.04245329 | E10: 0.038463746 | F10: 0.03642792 | G10: 0.036028127 | H10: 0.037515342 | I10: 0.037025046 | J10: 0.035960016 | K10: 0.036056116
A11: 0083.out | B11: 0.046041174 | C11: 0.049917359 | D11: 0.051672814 | E11: 0.04636073 | F11: 0.053117578 | G11: 0.044921565 | H11: 0.044815668 | I11: 0.046227309 | J11: 0.050033984 | K11: 0.047024566
A12: 0088.out | B12: 0.062463059 | C12: 0.05802287 | D12: 0.06159816 | E12: 0.062628668 | F12: 0.060845688 | G12: 0.070127258 | H12: 0.068206193 | I12: 0.06074539 | J12: 0.055832166 | K12: 0.054269377
A13: dlv
A14: dlv2
A15: 0002.out | B15: 0.00116766 | C15: 0.001157397 | D15: 0.001145734 | E15: 0.001153198 | F15: 0.001147134 | G15: 0.001135472 | H15: 0.001063164 | I15: 0.001060831 | J15: 0.001074359 | K15: 0.001055233
A16: 0007.out | B16: 6.3911e-05 | C16: 1.1196e-05 | D16: 1.7261e-05 | E16: 1.5394e-05 | F16: 1.6328e-05 | G16: 1.4461e-05 | H16: 1.2596e-05 | I16: 1.0729e-05 | J16: 1.4462e-05 | K16: 1.2129e-05
A17: 0024.out | B17: 0.004834851 | C17: 0.005119885 | D17: 0.005119418 | E17: 0.005236977 | F17: 0.005136212 | G17: 0.005191727 | H17: 0.005515481 | I17: 0.005368998 | J17: 0.005763194 | K17: 0.005661963
A18: 0027.out | B18: 0.026796007 | C18: 0.025639076 | D18: 0.025177703 | E18: 0.023803381 | F18: 0.022907693 | G18: 0.023715679 | H18: 0.022785003 | I18: 0.024549788 | J18: 0.024817562 | K18: 0.023582258
A19: 0041.out | B19: 0.002449148 | C19: 0.002463142 | D19: 0.002470141 | E19: 0.002339519 | F19: 0.002335321 | G19: 0.002325057 | H19: 0.002325524 | I19: 0.00228867 | J19: 0.002245752 | K19: 0.004823188
A20: 0048.out | B20: 0.00722102 | C20: 0.007286331 | D20: 0.006840352 | E20: 0.006896799 | F20: 0.00653899 | G20: 0.006629026 | H20: 0.006293143 | I20: 0.006348657 | J20: 0.006085548 | K20: 0.006206374
A21: 0062.out | B21: 0.012299852 | C21: 0.012602147 | D21: 0.013207669 | E21: 0.013325695 | F21: 0.014447172 | G21: 0.014932803 | H21: 0.014470963 | I21: 0.014345007 | J21: 0.01433661 | K21: 0.013723157
A22: 0066.out | B22: 0.024207841 | C22: 0.023865426 | D22: 0.025320454 | E22: 0.025710918 | F22: 0.024901066 | G22: 0.026638795 | H22: 0.026125173 | I22: 0.02638455 | J22: 0.026627598 | K22: 0.025987554
A23: 0081.out | B23: 0.032925873 | C23: 0.037407113 | D23: 0.045059649 | E23: 0.041229183 | F23: 0.040264919 | G23: 0.038748779 | H23: 0.039522243 | I23: 0.038592501 | J23: 0.037582053 | K23: 0.03828694
A24: 0083.out | B24: 0.045752875 | C24: 0.047546584 | D24: 0.04898575 | E24: 0.048532774 | F24: 0.047275078 | G24: 0.044362225 | H24: 0.045760339 | I24: 0.054897759 | J24: 0.04762589 | K24: 0.04670641
