Workbook
Name blocksworld: blocksworld!$A$1:$L$71
Name depots: depots!$A$1:$L$45
Name gripper: gripper!$A$1:$L$41
Name logistics: logistics!$A$1:$L$57

Sheet refined_data
C1: PDDL Mapper
C2: NEW | D2: OLD
A3: blocksworld 0001.out | C3: =AVERAGE(blocksworld!B1:K1) -> 0.0010520927 | D3: =AVERAGE(blocksworld!B37:K37) -> 0.0001837534
A4: blocksworld 0002.out | C4: =AVERAGE(blocksworld!B2:K2) -> 0.0002815784 | D4: =AVERAGE(blocksworld!B38:K38) -> 1.99196e-05
A5: blocksworld 0003.out | C5: =AVERAGE(blocksworld!B3:K3) -> 0.0002382404 | D5: =AVERAGE(blocksworld!B39:K39) -> 1.23623e-05
A6: blocksworld 0004.out | C6: =AVERAGE(blocksworld!B4:K4) -> 0.0003357385 | D6: =AVERAGE(blocksworld!B40:K40) -> 1.59543e-05
A7: blocksworld 0005.out | C7: =AVERAGE(blocksworld!B5:K5) -> 0.0002214465 | D7: =AVERAGE(blocksworld!B41:K41) -> 1.35285e-05
A8: blocksworld 0006.out | C8: =AVERAGE(blocksworld!B6:K6) -> 0.0002235456 | D8: =AVERAGE(blocksworld!B42:K42) -> 1.4135e-05
A9: blocksworld 0007.out | C9: =AVERAGE(blocksworld!B7:K7) -> 0.0001359374 | D9: =AVERAGE(blocksworld!B43:K43) -> 9.19e-06
A10: blocksworld 0008.out | C10: =AVERAGE(blocksworld!B8:K8) -> 0.0001155051 | D10: =AVERAGE(blocksworld!B44:K44) -> 1.13359e-05
A11: blocksworld 0009.out | C11: =AVERAGE(blocksworld!B9:K9) -> 0.000176523 | D11: =AVERAGE(blocksworld!B45:K45) -> 1.75403e-05
A12: blocksworld 0010.out | C12: =AVERAGE(blocksworld!B10:K10) -> 0.000133465 | D12: =AVERAGE(blocksworld!B46:K46) -> 1.68408e-05
A13: blocksworld 0011.out | C13: =AVERAGE(blocksworld!B11:K11) -> 0.0002025533 | D13: =AVERAGE(blocksworld!B47:K47) -> 2.12724e-05
A14: blocksworld 0012.out | C14: =AVERAGE(blocksworld!B12:K12) -> 0.0001170908 | D14: =AVERAGE(blocksworld!B48:K48) -> 1.36684e-05
... A37: blocksworld 0035.out | C37: =AVERAGE(blocksworld!B35:K35) -> 9.43727e-05 | D37: =AVERAGE(blocksworld!B71:K71) -> 1.67472e-05
A38: depots 0001.out | C38: =AVERAGE(depots!B1:K1) -> 5.6073e-05 | D38: =AVERAGE(depots!B24:K24) -> 5.5981e-06
A39: depots 0002.out | C39: =AVERAGE(depots!B2:K2) -> 6.07381e-05 | D39: =AVERAGE(depots!B25:K25) -> 5.8778e-06
A40: depots 0003.out | C40: =AVERAGE(depots!B3:K3) -> 0.0001224556 | D40: =AVERAGE(depots!B26:K26) -> 1.18958e-05
A41: depots 0004.out | C41: =AVERAGE(depots!B4:K4) -> 0.0001113531 | D41: =AVERAGE(depots!B27:K27) -> 1.18958e-05
A42: depots 0005.out | C42: =AVERAGE(depots!B5:K5) -> 0.0002843303 | D42: =AVERAGE(depots!B28:K28) -> 3.67603e-05
A43: depots 0006.out | C43: =AVERAGE(depots!B6:K6) -> 0.0001550175 | D43: =AVERAGE(depots!B29:K29) -> 1.88467e-05
A44: depots 0007.out | C44: =AVERAGE(depots!B7:K7) -> 9.46057e-05 | D44: =AVERAGE(depots!B30:K30) -> 1.07297e-05
A45: depots 0008.out | C45: =AVERAGE(depots!B8:K8) -> 0.0001664465 | D45: =AVERAGE(depots!B31:K31) -> 1.68405e-05
A46: depots 0009.out | C46: =AVERAGE(depots!B9:K9) -> 0.0002305432 | D46: =AVERAGE(depots!B32:K32) -> 2.28116e-05
A47: depots 0010.out | C47: =AVERAGE(depots!B10:K10) -> 8.36898e-05 | D47: =AVERAGE(depots!B33:K33) -> 9.2368e-06
A48: depots 0011.out | C48: =AVERAGE(depots!B11:K11) -> 0.0002013404 | D48: =AVERAGE(depots!B34:K34) -> 2.05726e-05
A49: depots 0012.out | C49: =AVERAGE(depots!B12:K12) -> 0.0003688133 | D49: =AVERAGE(depots!B35:K35) -> 3.52206e-05
... A59: depots 0022.out | C59: =AVERAGE(depots!B22:K22) -> 1.95928e-05 | D59: =AVERAGE(depots!B45:K45) -> 1.0728e-06
A60: gripper 0001.out | C60: =AVERAGE(gripper!B1:K1) -> 7.2727e-05 | D60: =AVERAGE(gripper!B22:K22) -> 5.4582e-06
A61: gripper 0002.out | C61: =AVERAGE(gripper!B2:K2) -> 9.59586e-05 | D61: =AVERAGE(gripper!B23:K23) -> 9.0035e-06
A62: gripper 0003.out | C62: =AVERAGE(gripper!B3:K3) -> 8.91479e-05 | D62: =AVERAGE(gripper!B24:K24) -> 9.0968e-06
A63: gripper 0004.out | C63: =AVERAGE(gripper!B4:K4) -> 9.30197e-05 | D63: =AVERAGE(gripper!B25:K25) -> 1.36216e-05
A64: gripper 0005.out | C64: =AVERAGE(gripper!B5:K5) -> 8.96142e-05 | D64: =AVERAGE(gripper!B26:K26) -> 1.24088e-05
A65: gripper 0006.out | C65: =AVERAGE(gripper!B6:K6) -> 0.0001119127 | D65: =AVERAGE(gripper!B27:K27) -> 1.44615e-05
A66: gripper 0007.out | C66: =AVERAGE(gripper!B7:K7) -> 0.0001154583 | D66: =AVERAGE(gripper!B28:K28) -> 1.61409e-05
A67: gripper 0008.out | C67: =AVERAGE(gripper!B8:K8) -> 0.0001251616 | D67: =AVERAGE(gripper!B29:K29) -> 1.85666e-05
A68: gripper 0009.out | C68: =AVERAGE(gripper!B9:K9) -> 0.0001342114 | D68: =AVERAGE(gripper!B30:K30) -> 1.95929e-05
A69: gripper 0010.out | C69: =AVERAGE(gripper!B10:K10) -> 0.0001479265 | D69: =AVERAGE(gripper!B31:K31) -> 2.22984e-05
A70: gripper 0011.out | C70: =AVERAGE(gripper!B11:K11) -> 0.0001615015 | D70: =AVERAGE(gripper!B32:K32) -> 2.52842e-05
A71: gripper 0012.out | C71: =AVERAGE(gripper!B12:K12) -> 0.0001696651 | D71: =AVERAGE(gripper!B33:K33) -> 2.5051e-05
...

Sheet blocksworld
A1: 0001.out | B1: 0.007618845 | C1: 0.000343809 | D1: 0.000304157 | E1: 0.000319084 | F1: 0.000353605 | G1: 0.000303224 | H1: 0.000324682 | I1: 0.000427312 | J1: 0.000293893 | K1: 0.000232316
A2: 0002.out | B2: 0.000434777 | C2: 0.00025051 | D2: 0.000256574 | E2: 0.000256107 | F2: 0.000370399 | G2: 0.000279899 | H2: 0.000256574 | I2: 0.000243046 | J2: 0.000263105 | K2: 0.000204793
A3: 0003.out | B3: 0.000262171 | C3: 0.000292028 | D3: 0.000264504 | E3: 0.000186599 | F3: 0.000233249 | G3: 0.000191264 | H3: 0.000202927 | I3: 0.000179602 | J3: 0.000278499 | K3: 0.000291561
A4: 0004.out | B4: 0.000457635 | C4: 0.000401188 | D4: 0.00035967 | E4: 0.000369932 | F4: 0.000300891 | G4: 0.000313953 | H4: 0.000299492 | I4: 0.00029296 | J4: 0.000268703 | K4: 0.000292961
A5: 0005.out | B5: 0.000393725 | C5: 0.000338211 | D5: 0.000186132 | E5: 0.000214123 | F5: 0.000182867 | G5: 0.000234648 | H5: 0.000147413 | I5: 0.000201994 | J5: 0.00015441 | K5: 0.000160942
A6: 0006.out | B6: 0.00021319 | C6: 0.000383461 | D6: 0.000207125 | E6: 0.000219254 | F6: 0.000159076 | G6: 0.000175869 | H6: 0.000136217 | I6: 0.000168405 | J6: 0.000408652 | K6: 0.000164207
A7: 0007.out | B7: 0.000243512 | C7: 0.000122689 | D7: 0.000125488 | E7: 0.000142748 | F7: 0.000134351 | G7: 0.000111493 | H7: 0.000140416 | I7: 0.000124088 | J7: 0.000109627 | K7: 0.000104962
A8: 0008.out | B8: 0.00011196 | C8: 9.7498e-05 | D8: 9.3766e-05 | E8: 0.000101697 | F8: 0.000126421 | G8: 0.000180535 | H8: 0.000126888 | I8: 9.5632e-05 | J8: 0.000104962 | K8: 0.000115692
A9: 0009.out | B9: 0.000208991 | C9: 0.000160942 | D9: 0.000153945 | E9: 0.000163274 | F9: 0.000150678 | G9: 0.000146481 | H9: 0.000146014 | I9: 0.000209925 | J9: 0.000172604 | K9: 0.000252376
A10: 0010.out | B10: 0.000233249 | C10: 0.000134818 | D10: 0.000144148 | E10: 0.000145547 | F10: 0.000108227 | G10: 0.000106828 | H10: 0.000111493 | I10: 0.000109627 | J10: 0.000122222 | K10: 0.000118491
A11: 0011.out | B11: 0.000247244 | C11: 0.000145547 | D11: 0.000156277 | E11: 0.000153478 | F11: 0.00015581 | G11: 0.000237447 | H11: 0.000245844 | I11: 0.000237447 | J11: 0.000230916 | K11: 0.000215523
A12: 0012.out | B12: 0.000164674 | C12: 0.000112426 | D12: 0.00011849 | E12: 0.000107294 | F12: 0.000118024 | G12: 0.000104962 | H12: 9.8431e-05 | I12: 0.000104962 | J12: 0.000117557 | K12: 0.000124088
... A71: 0035.out | B71: 1.9593e-05 | C71: 1.6327e-05 | D71: 1.866e-05 | E71: 1.4928e-05 | F71: 1.6327e-05 | G71: 1.6328e-05 | H71: 1.6794e-05 | I71: 1.4461e-05 | J71: 1.6327e-05 | K71: 1.7727e-05

Sheet depots
A1: 0001.out | B1: 0.000168405 | C1: 4.8049e-05 | D1: 4.4317e-05 | E1: 4.6183e-05 | F1: 4.4317e-05 | G1: 4.2451e-05 | H1: 4.1519e-05 | I1: 4.2451e-05 | J1: 4.1519e-05 | K1: 4.1519e-05
A2: 0002.out | B2: 0.00011989 | C2: 5.7379e-05 | D2: 5.5047e-05 | E2: 5.2714e-05 | F2: 5.3181e-05 | G2: 5.3181e-05 | H2: 5.3181e-05 | I2: 5.6913e-05 | J2: 5.3181e-05 | K2: 5.2714e-05
A3: 0003.out | B3: 0.000196862 | C3: 0.000108228 | D3: 0.000113825 | E3: 0.000112426 | F3: 0.000112892 | G3: 0.000112426 | H3: 0.000112426 | I3: 0.000112426 | J3: 0.00012922 | K3: 0.000113825
A4: 0004.out | B4: 0.000158143 | C4: 9.8898e-05 | D4: 9.7032e-05 | E4: 0.000119424 | F4: 0.000121289 | G4: 0.000148346 | H4: 9.33e-05 | I4: 9.2366e-05 | J4: 9.2367e-05 | K4: 9.2366e-05
A5: 0005.out | B5: 0.000343342 | C5: 0.000273834 | D5: 0.000274767 | E5: 0.00028643 | F5: 0.000280365 | G5: 0.000276634 | H5: 0.000283631 | I5: 0.0002743 | J5: 0.000276633 | K5: 0.000273367
A6: 0006.out | B6: 0.000172604 | C6: 0.000153478 | D6: 0.000153012 | E6: 0.000158143 | F6: 0.000153012 | G6: 0.000151146 | H6: 0.000150679 | I6: 0.000151146 | J6: 0.000156277 | K6: 0.000150678
A7: 0007.out | B7: 0.000102629 | C7: 0.000105428 | D7: 0.000110094 | E7: 0.000106828 | F7: 8.6302e-05 | G7: 9.0034e-05 | H7: 8.4903e-05 | I7: 8.7235e-05 | J7: 8.6302e-05 | K7: 8.6302e-05
A8: 0008.out | B8: 0.000163741 | C8: 0.000181934 | D8: 0.000162808 | E8: 0.000160942 | F8: 0.000158143 | G8: 0.00017307 | H8: 0.000167006 | I8: 0.000168406 | J8: 0.000165141 | K8: 0.000163274
A9: 0009.out | B9: 0.000255174 | C9: 0.000228117 | D9: 0.000227185 | E9: 0.000230916 | F9: 0.000229517 | G9: 0.000224852 | H9: 0.000224386 | I9: 0.000224852 | J9: 0.000234648 | K9: 0.000225785
A10: 0010.out | B10: 8.9568e-05 | C10: 7.9771e-05 | D10: 8.257e-05 | E10: 7.8372e-05 | F10: 7.8371e-05 | G10: 8.3037e-05 | H10: 8.2103e-05 | I10: 8.2104e-05 | J10: 9.5166e-05 | K10: 8.5836e-05
A11: 0011.out | B11: 0.000216455 | C11: 0.000199195 | D11: 0.000199661 | E11: 0.000201527 | F11: 0.000198728 | G11: 0.000201993 | H11: 0.000198728 | I11: 0.000199194 | J11: 0.000199661 | K11: 0.000198262
A12: 0012.out | B12: 0.000350807 | C12: 0.000368533 | D12: 0.000356405 | E12: 0.000367134 | F12: 0.00037833 | G12: 0.000372732 | H12: 0.000389059 | I12: 0.000389992 | J12: 0.000362469 | K12: 0.000352672
... A45: 0022.out | B45: 9.33e-07 | C45: 9.33e-07 | D45: 9.33e-07 | E45: 9.33e-07 | F45: 1.399e-06 | G45: 1.399e-06 | H45: 9.33e-07 | I45: 9.33e-07 | J45: 9.33e-07 | K45: 1.399e-06

Sheet gripper
A1: 0001.out | B1: 0.000101697 | C1: 6.9042e-05 | D1: 5.8778e-05 | E1: 7.6039e-05 | F1: 7.5106e-05 | G1: 7.3707e-05 | H1: 7.2774e-05 | I1: 6.4844e-05 | J1: 6.7175e-05 | K1: 6.8108e-05
A2: 0002.out | B2: 0.000104495 | C2: 9.5632e-05 | D2: 8.3037e-05 | E2: 0.000105895 | F2: 8.6769e-05 | G2: 0.000106828 | H2: 0.000104962 | I2: 9.4699e-05 | J2: 8.9101e-05 | K2: 8.8168e-05
A3: 0003.out | B3: 0.000130153 | C3: 0.000128754 | D3: 0.000109627 | E3: 0.000132485 | F3: 6.7642e-05 | G3: 6.8109e-05 | H3: 6.2978e-05 | I3: 6.4377e-05 | J3: 6.5776e-05 | K3: 6.1578e-05
A4: 0004.out | B4: 0.000132019 | C4: 0.000123622 | D4: 0.00012922 | E4: 8.8168e-05 | F4: 7.4173e-05 | G4: 7.8372e-05 | H4: 7.7905e-05 | I4: 7.4173e-05 | J4: 7.6972e-05 | K4: 7.5573e-05
A5: 0005.out | B5: 0.000107761 | C5: 9.1434e-05 | D5: 8.5369e-05 | E5: 9.0034e-05 | F5: 8.5369e-05 | G5: 8.6302e-05 | H5: 8.8634e-05 | I5: 8.7702e-05 | J5: 8.8168e-05 | K5: 8.5369e-05
A6: 0006.out | B6: 0.000208991 | C6: 0.00011849 | D6: 0.00010123 | E6: 9.8898e-05 | F6: 9.8897e-05 | G6: 9.8431e-05 | H6: 0.000101696 | I6: 9.7032e-05 | J6: 9.7498e-05 | K6: 9.7964e-05
A7: 0007.out | B7: 0.000118024 | C7: 0.000118024 | D7: 0.000111493 | E7: 0.00012129 | F7: 0.000111493 | G7: 0.000110094 | H7: 0.00010916 | I7: 0.000115691 | J7: 0.000117091 | K7: 0.000122223
A8: 0008.out | B8: 0.000141349 | C8: 0.000122689 | D8: 0.000123156 | E8: 0.000127354 | F8: 0.000120823 | G8: 0.000120357 | H8: 0.000125022 | I8: 0.000121756 | J8: 0.00012922 | K8: 0.00011989
A9: 0009.out | B9: 0.000154877 | C9: 0.000135751 | D9: 0.000131086 | E9: 0.000130153 | F9: 0.000131552 | G9: 0.00013062 | H9: 0.000132019 | I9: 0.000136217 | J9: 0.00012922 | K9: 0.000130619
A10: 0010.out | B10: 0.000181468 | C10: 0.000144615 | D10: 0.000142748 | E10: 0.000144148 | F10: 0.000141815 | G10: 0.000142749 | H10: 0.000142748 | I10: 0.000150679 | J10: 0.000145547 | K10: 0.000142748
A11: 0011.out | B11: 0.000172604 | C11: 0.000156277 | D11: 0.000154411 | E11: 0.000155343 | F11: 0.000160008 | G11: 0.000154877 | H11: 0.000154411 | I11: 0.000155344 | J11: 0.000154411 | K11: 0.000197329
A12: 0012.out | B12: 0.000187065 | C12: 0.000167006 | D12: 0.000167006 | E12: 0.000166539 | F12: 0.000172138 | G12: 0.00016654 | H12: 0.000167006 | I12: 0.000171671 | J12: 0.000165606 | K12: 0.000166074
... A41: 0020.out | B41: 4.3851e-05 | C41: 3.9652e-05 | D41: 4.1985e-05 | E41: 3.8253e-05 | F41: 3.732e-05 | G41: 7.5106e-05 | H41: 4.1518e-05 | I41: 3.9186e-05 | J41: 4.3385e-05 | K41: 3.7786e-05

Sheet logistics
A1: 0001.out | B1: 0.000137617 | C1: 6.8109e-05 | D1: 6.4376e-05 | E1: 6.2044e-05 | F1: 5.9711e-05 | G1: 5.9245e-05 | H1: 5.9245e-05 | I1: 5.9245e-05 | J1: 5.9712e-05 | K1: 5.8779e-05
A2: 0002.out | B2: 7.5106e-05 | C2: 6.7176e-05 | D2: 6.531e-05 | E2: 6.7176e-05 | F2: 6.6243e-05 | G2: 7.324e-05 | H2: 6.5776e-05 | I2: 6.6242e-05 | J2: 6.8109e-05 | K2: 6.5776e-05
A3: 0003.out | B3: 5.1315e-05 | C3: 4.3384e-05 | D3: 4.2917e-05 | E3: 4.2918e-05 | F3: 4.2918e-05 | G3: 4.2917e-05 | H3: 4.2918e-05 | I3: 4.3384e-05 | J3: 4.2918e-05 | K3: 4.3384e-05
A4: 0004.out | B4: 8.6302e-05 | C4: 7.9305e-05 | D4: 7.7905e-05 | E4: 7.7438e-05 | F4: 8.9567e-05 | G4: 8.8635e-05 | H4: 8.8634e-05 | I4: 8.8635e-05 | J4: 8.3037e-05 | K4: 0.000104029
A5: 0005.out | B5: 0.000111493 | C5: 9.3766e-05 | D5: 7.3707e-05 | E5: 7.5572e-05 | F5: 0.000105428 | G5: 6.2044e-05 | H5: 6.9042e-05 | I5: 5.9711e-05 | J5: 6.391e-05 | K5: 6.0644e-05
A6: 0006.out | B6: 7.0441e-05 | C6: 7.0441e-05 | D6: 6.9041e-05 | E6: 6.5776e-05 | F6: 6.5309e-05 | G6: 5.2715e-05 | H6: 4.6183e-05 | I6: 3.9186e-05 | J6: 3.4987e-05 | K6: 3.7787e-05
A7: 0007.out | B7: 8.7235e-05 | C7: 6.9508e-05 | D7: 6.9042e-05 | E7: 6.8576e-05 | F7: 6.8109e-05 | G7: 6.8575e-05 | H7: 6.8109e-05 | I7: 6.7642e-05 | J7: 6.8575e-05 | K7: 6.9508e-05
A8: 0008.out | B8: 4.8516e-05 | C8: 4.0585e-05 | D8: 4.0119e-05 | E8: 4.0119e-05 | F8: 4.0119e-05 | G8: 5.8779e-05 | H8: 4.525e-05 | I8: 4.3384e-05 | J8: 4.2918e-05 | K8: 4.0585e-05
A9: 0009.out | B9: 9.1901e-05 | C9: 7.9771e-05 | D9: 7.6972e-05 | E9: 7.6039e-05 | F9: 7.5106e-05 | G9: 7.4173e-05 | H9: 7.5572e-05 | I9: 7.5106e-05 | J9: 0.000103562 | K9: 8.9101e-05
A10: 0010.out | B10: 9.6565e-05 | C10: 8.3036e-05 | D10: 8.257e-05 | E10: 8.4436e-05 | F10: 8.1171e-05 | G10: 8.4902e-05 | H10: 7.8371e-05 | I10: 7.8372e-05 | J10: 7.8372e-05 | K10: 8.0705e-05
A11: 0011.out | B11: 0.000126421 | C11: 0.000115225 | D11: 0.00011989 | E11: 0.00012129 | F11: 0.000120356 | G11: 0.000120357 | H11: 0.000124088 | I11: 0.000119423 | J11: 0.000120356 | K11: 0.000120357
A12: 0012.out | B12: 0.000144148 | C12: 0.000120357 | D12: 0.000121756 | E12: 0.000120823 | F12: 0.000125488 | G12: 0.00012782 | H12: 0.000118957 | I12: 0.000118024 | J12: 0.000119424 | K12: 0.000118957
... A57: 0028.out | B57: 1.4462e-05 | C57: 1.1662e-05 | D57: 1.1663e-05 | E57: 1.1662e-05 | F57: 1.1662e-05 | G57: 1.2596e-05 | H57: 1.2595e-05 | I57: 1.2596e-05 | J57: 1.2596e-05 | K57: 1.2595e-05
